Workbook

Sheet TB-22
A1: Dynamic Air Engineering (India) Pvt Ltd
A2: No:4, Boopathy Nagar,Industrial Estate,
A3: Keelkattalai,Chennai - 600 117.
A4: CIN: U2912TN2008PTC066303 | E4: 1000
A6: Trial Balance for the period | B6: 01-04-2021 TO 31-03-2022
A8: Particulars | B8: Debit | C8: Credit | E8: Check
A10: Opening Stock | B10: 56896.007 | C10: 0 | E10: =VLOOKUP(A10,'Link Sheet'!A:A,1,0) -> Opening Stock
A11: Ace Metro Enterprises | B11: 234.421 | C11: 0 | E11: =VLOOKUP(A11,'Link Sheet'!A:A,1,0) -> Ace Metro Enterprises
A12: AC Zone Private Limited | B12: 4.543 | C12: 0 | E12: =VLOOKUP(A12,'Link Sheet'!A:A,1,0) -> AC Zone Private Limited
A13: Adithya Wire Mesh Solutions | B13: 167.54 | C13: 0 | E13: =VLOOKUP(A13,'Link Sheet'!A:A,1,0) -> Adithya Wire Mesh Solutions
A14: Advance Paints Pvt Ltd | B14: 0 | C14: 77.88 | E14: =VLOOKUP(A14,'Link Sheet'!A:A,1,0) -> Advance Paints Pvt Ltd
A15: Advance Tax | B15: 3000 | C15: 0 | E15: =VLOOKUP(A15,'Link Sheet'!A:A,1,0) -> Advance Tax
A16: Advertising Expenses | B16: 23.732 | C16: 0 | E16: =VLOOKUP(A16,'Link Sheet'!A:A,1,0) -> Advertising Expenses
A17: Air Clime Engineers | B17: 1.7 | C17: 0 | E17: =VLOOKUP(A17,'Link Sheet'!A:A,1,0) -> Air Clime Engineers
A18: Air Comfort | B18: 40.202 | C18: 0 | E18: =VLOOKUP(A18,'Link Sheet'!A:A,1,0) -> Air Comfort
A19: Airconditioners | B19: 199.784 | C19: 0 | E19: =VLOOKUP(A19,'Link Sheet'!A:A,1,0) -> Airconditioners
A20: Air Cool | B20: 29.058 | C20: 0 | E20: =VLOOKUP(A20,'Link Sheet'!A:A,1,0) -> Air Cool
A21: Airflow Equipments India Pvt Limited | B21: 1048.948 | C21: 0 | E21: =VLOOKUP(A21,'Link Sheet'!A:A,1,0) -> Airflow Equipments India Pvt Limited
... A454: Zita & Company | B454: 0 | C454: 15 | E454: =VLOOKUP(A454,'Link Sheet'!A:A,1,0) -> Zita & Company
A455: Grand Total | B455: =SUM(B10:B454) -> 1040082.1 | C455: =SUM(C10:C454) -> 1040082.1

Sheet Link Sheet
A2: Subschedules to Financial Statements | B2: DEBIT | C2: CREDIT | D2: NETT
A4: SHARE CAPITAL. | D4: =+B4-C4 -> 0
A5: Share Capital | B5: =IF(ISNA(VLOOKUP(A5,'TB-22'!A:C,2,0)),0,VLOOKUP(A5,'TB-22'!A:C,2,0)) -> 0 | C5: =IF(ISNA(VLOOKUP(A5,'TB-22'!A:C,3,0)),0,VLOOKUP(A5,'TB-22'!A:C,3,0)) -> 28500 | D5: =+B5-C5 -> -28500 | F5: =D5 -> -28500
D6: =+B6-C6 -> 0
A7: RESERVES AND SURPLUS | D7: =+B7-C7 -> 0
A8: Share Premium | B8: =IF(ISNA(VLOOKUP(A8,'TB-22'!A:C,2,0)),0,VLOOKUP(A8,'TB-22'!A:C,2,0)) -> 0 | C8: =IF(ISNA(VLOOKUP(A8,'TB-22'!A:C,3,0)),0,VLOOKUP(A8,'TB-22'!A:C,3,0)) -> 16200 | D8: =+B8-C8 -> -16200
D9: =+B9-C9 -> 0
A10: Reserve & Surplus | B10: =IF(ISNA(VLOOKUP(A10,'TB-22'!A:C,2,0)),0,VLOOKUP(A10,'TB-22'!A:C,2,0)) -> 0 | C10: =IF(ISNA(VLOOKUP(A10,'TB-22'!A:C,3,0)),0,VLOOKUP(A10,'TB-22'!A:C,3,0)) -> 39257.515 | D10: =+B10-C10 -> -39257.515 | F10: =SUM(D8:D10) -> -55457.515
D11: =+B11-C11 -> 0
A12: LONG-TERM BORROWINGS | D12: =+B12-C12 -> 0
A13: ( a) Vehicle HP Loans - Banks | D13: =+B13-C13 -> 0
A14: Kotak Bank Vehicle Loan | B14: =IF(ISNA(VLOOKUP(A14,'TB-22'!A:C,2,0)),0,VLOOKUP(A14,'TB-22'!A:C,2,0)) -> 0 | C14: =IF(ISNA(VLOOKUP(A14,'TB-22'!A:C,3,0)),0,VLOOKUP(A14,'TB-22'!A:C,3,0)) -> 209.6 | D14: =+B14-C14 -> -209.6
A15: Indian Bank Vehicle Loan 7145753131 | B15: =IF(ISNA(VLOOKUP(A15,'TB-22'!A:C,2,0)),0,VLOOKUP(A15,'TB-22'!A:C,2,0)) -> 0 | C15: =IF(ISNA(VLOOKUP(A15,'TB-22'!A:C,3,0)),0,VLOOKUP(A15,'TB-22'!A:C,3,0)) -> 683.063 | D15: =+B15-C15 -> -683.063
D16: =+B16-C16 -> 0
A17: (c) Loan from Banks (secured by the immovable proerty and Machineries of the company) | D17: =+B17-C17 -> 0
A18: Indian Bank TL1 A/c No: 6613793057 | B18: =IF(ISNA(VLOOKUP(A18,'TB-22'!A:C,2,0)),0,VLOOKUP(A18,'TB-22'!A:C,2,0)) -> 0 | C18: =IF(ISNA(VLOOKUP(A18,'TB-22'!A:C,3,0)),0,VLOOKUP(A18,'TB-22'!A:C,3,0)) -> 27194.129 | D18: =+B18-C18 -> -27194.129
A19: Indian Bank TL2 A/c No: 6613796127 | B19: =IF(ISNA(VLOOKUP(A19,'TB-22'!A:C,2,0)),0,VLOOKUP(A19,'TB-22'!A:C,2,0)) -> 0 | C19: =IF(ISNA(VLOOKUP(A19,'TB-22'!A:C,3,0)),0,VLOOKUP(A19,'TB-22'!A:C,3,0)) -> 97806.491 | D19: =+B19-C19 -> -97806.491
A20: Indian Bank TL3 GECL A/c No: 6887518087 | B20: =IF(ISNA(VLOOKUP(A20,'TB-22'!A:C,2,0)),0,VLOOKUP(A20,'TB-22'!A:C,2,0)) -> 0 | C20: =IF(ISNA(VLOOKUP(A20,'TB-22'!A:C,3,0)),0,VLOOKUP(A20,'TB-22'!A:C,3,0)) -> 32498.903 | D20: =+B20-C20 -> -32498.903
A21: Inidan Bank TL4 GECL A/c No. 7124472429 | B21: =IF(ISNA(VLOOKUP(A21,'TB-22'!A:C,2,0)),0,VLOOKUP(A21,'TB-22'!A:C,2,0)) -> 0 | C21: =IF(ISNA(VLOOKUP(A21,'TB-22'!A:C,3,0)),0,VLOOKUP(A21,'TB-22'!A:C,3,0)) -> 18516.842 | D21: =+B21-C21 -> -18516.842
D22: =+B22-C22 -> 0
A23: Unsecured Loans | D23: =+B23-C23 -> 0
B24: =IF(ISNA(VLOOKUP(A24,'TB-22'!A:C,2,0)),0,VLOOKUP(A24,'TB-22'!A:C,2,0)) -> 0 | C24: =IF(ISNA(VLOOKUP(A24,'TB-22'!A:C,3,0)),0,VLOOKUP(A24,'TB-22'!A:C,3,0)) -> 0 | D24: =+B24-C24 -> 0
D25: =+B25-C25 -> 0 | F25: =SUM(D14:D25) -> -176909.03
A26: DEFERRED TAX ASSETS/(LIABILITIES) (NET) | D26: =+B26-C26 -> 0
A27: Deferrd Tax Liability | B27: =IF(ISNA(VLOOKUP(A27,'TB-22'!A:C,2,0)),0,VLOOKUP(A27,'TB-22'!A:C,2,0)) -> 0 | C27: =IF(ISNA(VLOOKUP(A27,'TB-22'!A:C,3,0)),0,VLOOKUP(A27,'TB-22'!A:C,3,0)) -> 4666.3068 | D27: =+B27-C27 -> -4666.3068 | F27: =D27 -> -4666.3068
D28: =+B28-C28 -> 0
A29: LONG-TERM PROVISIONS | D29: =+B29-C29 -> 0
A30: Provision for Gratuity | B30: =IF(ISNA(VLOOKUP(A30,'TB-22'!A:C,2,0)),0,VLOOKUP(A30,'TB-22'!A:C,2,0)) -> 0 | C30: =IF(ISNA(VLOOKUP(A30,'TB-22'!A:C,3,0)),0,VLOOKUP(A30,'TB-22'!A:C,3,0)) -> 742.962 | D30: =+B30-C30 -> -742.962 | F30: =D30 -> -742.962
D31: =+B31-C31 -> 0
A32: SHORT-TERM BORROWINGS | D32: =+B32-C32 -> 0
A33: Indian Bank OCC A/c No:6613788934 | B33: =IF(ISNA(VLOOKUP(A33,'TB-22'!A:C,2,0)),0,VLOOKUP(A33,'TB-22'!A:C,2,0)) -> 0 | C33: =IF(ISNA(VLOOKUP(A33,'TB-22'!A:C,3,0)),0,VLOOKUP(A33,'TB-22'!A:C,3,0)) -> 37687.912 | D33: =+B33-C33 -> -37687.912 | F33: =D33 -> -37687.912
A34: NSIC - Bill Discounting Account | B34: =IF(ISNA(VLOOKUP(A34,'TB-22'!A:C,2,0)),0,VLOOKUP(A34,'TB-22'!A:C,2,0)) -> 0 | C34: =IF(ISNA(VLOOKUP(A34,'TB-22'!A:C,3,0)),0,VLOOKUP(A34,'TB-22'!A:C,3,0)) -> 29505.835 | D34: =+B34-C34 -> -29505.835
D35: =+B35-C35 -> 0
A36: TRADE PAYABLES | D36: =+B36-C36 -> 0
A37: (i) Trade payables - Related Party | D37: =+B37-C37 -> 0
A38: Karthik Industries | B38: =IF(ISNA(VLOOKUP(A38,'TB-22'!A:C,2,0)),0,VLOOKUP(A38,'TB-22'!A:C,2,0)) -> 0 | C38: =IF(ISNA(VLOOKUP(A38,'TB-22'!A:C,3,0)),0,VLOOKUP(A38,'TB-22'!A:C,3,0)) -> 7419.6566 | D38: =+B38-C38 -> -7419.6566
A39: (ii) Payables - For Capital expenses | D39: =+B39-C39 -> 0
A40: Naga Welders | B40: =IF(ISNA(VLOOKUP(A40,'TB-22'!A:C,2,0)),0,VLOOKUP(A40,'TB-22'!A:C,2,0)) -> 0 | C40: =IF(ISNA(VLOOKUP(A40,'TB-22'!A:C,3,0)),0,VLOOKUP(A40,'TB-22'!A:C,3,0)) -> 1500.622 | D40: =+B40-C40 -> -1500.622
A41: K2 Cranes & Components P Ltd | B41: =IF(ISNA(VLOOKUP(A41,'TB-22'!A:C,2,0)),0,VLOOKUP(A41,'TB-22'!A:C,2,0)) -> 0 | C41: =IF(ISNA(VLOOKUP(A41,'TB-22'!A:C,3,0)),0,VLOOKUP(A41,'TB-22'!A:C,3,0)) -> 220.524 | D41: =+B41-C41 -> -220.524
A42: Pacific Weld Systems Pvt Ltd | B42: =IF(ISNA(VLOOKUP(A42,'TB-22'!A:C,2,0)),0,VLOOKUP(A42,'TB-22'!A:C,2,0)) -> 0 | C42: =IF(ISNA(VLOOKUP(A42,'TB-22'!A:C,3,0)),0,VLOOKUP(A42,'TB-22'!A:C,3,0)) -> 4.814 | D42: =+B42-C42 -> -4.814
...

Sheet STI 
A1: Index
C3: STATEMENT OF TOTAL INCOME FOR THE YEAR ENDED 31-3-2022
C5: Name of the Assessee | D5: =+BS!A1 -> DYNAMIC AIR ENGINEERING INDIA PRIVATE LIMITED
D6: CIN : U29192TN2008PTC066303
C8: Permanent Account Number | D8: AACCD 9024 A
C10: CIN No. | D10: U29192TN2008PTC066303
C12: Status | D12: Company (Domestic company in which public are not substantially interested)
H13: DISALLOWANCE FROM FORM 3CD
C14: Assessment Year | D14: 2022 - 2023 | H14: 36(1)(va) | I14: 3212
C16: Previous Year | D16: 2021 - 2022 | H16: 40A(3)
H17: 40(a)(ia) | I17: 762506.92
C18: Particulars
C19: INCOME FROM BUSINESS
C21: Profit before Tax as per Profit and Loss Account | F21: =+PL!E22*1000 -> 11220478
C23: Add : Depreciation as per books | E23: =+PL!E15*1000 -> 32221600
C24: Disallowance u/s 40A(3) | D24: Cash payments exceeding Rs.10,000 | E24: =+I16 -> 0 | J24: =I24-H24 -> 0
C25: Disallowance u/s 36(1)(va) | D25: EPF & ESI Employee Contribution | E25: =I14 -> 3212 | J25: =I25-H25 -> 0
C26: Disallowance u/s 40(a)(ia) | D26: Non deduction of TDS | E26: =I17*30/100 -> 228752.08
C27: Disallowance u/s 40(a)(ii) | D27: Interest on income tax | E27: =+'Link Sheet'!D601*1000 -> 234228
C28: Disallowance u/s 37 | D28: Interest on TDS & Penalty | E28: =SUM('Link Sheet'!D602:D603)*1000 -> 266229 | F28: =SUM(E23:E28) -> 32954021
C30: Less: Depreciation allowable u/s 32 | E30: =+'Dep IT'!I39+'Dep IT'!J39 -> 25806010
C31: Less: Income taxable under other heads | E31: =+'PL Notes'!C21*1000 -> 391314 | F31: =SUM(E30:E31) -> 26197324
F32: =+F21+F28-F31 -> 17977175
C33: INCOME FROM OTHER SOURCES
C34: Interest on Deposits | E34: =+'PL Notes'!C21*1000 -> 391314
F35: =+SUM(E34:E35) -> 391314
C37: Gross Total Income | F37: =SUM(F32:F36) -> 18368489
C39: Less: Deduction U/ch VIA | F39: 0
C40: Total Taxable Income | F40: =+F37-F39 -> 18368489
D41: Income Rounded off to Rs. | F41: =ROUNDUP(F40,-1) -> 18368490
C43: COMPUTATION OF TAX LIABILITY
C44: Tax on Total Taxable Income @ 25% | E44: A | F44: =+IF(F41*25%>0,F41*25%,0) -> 4592122.5
C45: Tax Under Minimum Alternate Tax (MAT) | E45: B | F45: ='115JB '!E50 -> 1872922.5
C46: Tax | E46: (Higher of A & B) | F46: =+MAX(F44,F45) -> 4592122.5
C47: Add: Surcharge @ 7% | F47: =IF(F41>10000000,'STI '!F46*0.07,0) -> 321448.58
C48: Tax Before Education Cess | F48: =+F46+F47 -> 4913571.1
C49: Add: Education Cess @ 4% | F49: =+F48*4% -> 196542.84
C50: TOTAL TAX LIABILITY | F50: =+ROUND(F48+F49,-1) -> 5110110
C51: Less: MAT Credit Utilised
C52: Less: Tax Deducted at Source | F52: =557733-866 -> 556867 | G52: 866 Rs to be c/f
...

Sheet 115JB 
A1: Index
B2: STATEMENT OF TOTAL INCOME
B4: Name of the Assessee : DYNAMIC AIR ENGINEERING (INDIA) PRIVATE LIMITED
B6: Permanent Account Number : AACCD 9024 A
B8: Status : Company (Domestic company in which public are not substantially interested)
B10: Assessment Year : 2022-2023
B12: Previous Year : 2021-2022
B14: Particulars | D14: Amount | E14: Amount
B16: Profit as per Profit and Loss Account | E16: ='STI '!F21 -> 11220478
B17: Add: If the following are debited to the P&L Account
B18: Income tax Payable (includes interst on belated payments) | D18: 0
B19: Amount carried to Reserves | D19: 0
B20: Unascertained liabilities | D20: 0
B21: Provision for subsidiary losses | D21: 0
B22: Dividends Payable | D22: 0
B23: Expenses relating to amounts exempted u/s 10/11/12 | D23: 0
B24: Amount of Depreciation | D24: =+PL!E15*1000 -> 32221600
B25: Amount of Deferred Tax & provision thereof | D25: 0
B26: Amounts set aside as provision for diminution in the value of any asset | D26: 0
E27: =+SUM(D18:D27) -> 32221600
E28: =+E16+E27 -> 43442078
B29: Less: If the following are Credited to the P&L Account
B30: Amounts withdrawn from Reserves | D30: 0
B31: Income exempted u/s 10/11/12 other than 10(38) | D31: 0
B32: Amounts debited as depreciation (except depreciation on revaluation of assets) | D32: =+PL!E15*1000 -> 32221600
B33: Amount withdrawn from revaluation reserve and credited to the profit and loss account, | D33: 0
B34: (to the extent it does not exceed the amount of depreciation on account of revaluation of assets)
B35: Amount of loss brought forward or unabsorbed depreciation | D35: 0
B36: Amounts allowable as deduction u/s 80HHC/HHE/HHF | D36: 0
B37: Amount of deferred tax if credited to P&L | D37: 0
D38: 0 | E38: =SUM(D30:D38) -> 32221600
B40: Book Profit U/S 115JB | E40: =E28-E38 -> 11220478
B42: TAX PARTICULARS
B44: 15% of Book Profit | E44: =MAX(ROUND((ROUND(E40,-1)*15%),0),0) -> 1683072
B46: Tax Before Surcharge | E46: =+E44 -> 1683072
B47: Add : Surcharge@7% | E47: =IF(E40>10000000,E46*7%,0) -> 117815.04
B48: Tax Before Education Cess | E48: =+E46+E47 -> 1800887
B49: Add : Education Cess @ 4 % | E49: =+E48*4% -> 72035.482
B50: Tax Liability | E50: =+E48+E49 -> 1872922.5

Sheet Dep IT
A2: M/S DYNAMIC AIR ENGINEERING INDIA PRIVATE LIMITED
A3: CIN No. : U29192TN2008PTC066303
A4: REGISTERED OFFICE
A5: NO. 4, BOOPATHY NAGAR, INDUSTRIAL ESTATE
A6: KEEZHKATTALAI, CHENNAI - 600 117.
A8: DEPRECIATION STATEMENT AS PER INCOME TAX ACT 1961 FOR THE YEAR ENDED 31-03-2022
D9: GROSS BLOCK | K9: NET BLOCK
A10: SLNO | B10: PARTICULARS | C10: % | D10: AS ON 31-03-2021 | E10: ADDITIONS | G10: DELETIONS | H10: AS ON 31-03-2022 | I10: DEPRECIATION | J10: ADDITIONAL DEPRECIATION | K10: WDV AS ON 31-03-2022
E11: Before Sep | F11: After Sep
B12: BLOCK - I
A13: 1 | B13: Land | C13: 0 | D13: 24942539 | E13: 0 | F13: 0 | G13: 0 | H13: =+D13+E13+F13-G13 -> 24942539 | I13: =+((D13+E13-G13)*C13)+(F13*C13/2) -> 0 | K13: =+H13-I13-J13 -> 24942539
D14: 24942539 | E14: =SUM(E13) -> 0 | F14: =SUM(F13) -> 0 | G14: =SUM(G13) -> 0 | H14: =SUM(H13) -> 24942539 | I14: 0 | J14: =SUM(J13) -> 0 | K14: =SUM(K13) -> 24942539
B15: BLOCK - II 10%
A16: 2 | B16: Buildings | C16: 0.1 | D16: 58924903 | E16: 0 | F16: 0 | G16: 0 | H16: =+D16+E16+F16-G16 -> 58924903 | I16: =+((D16+E16-G16)*C16)+(F16*C16/2) -> 5892490.3 | K16: =+H16-I16-J16 -> 53032412
A17: =+A16+1 -> 3 | B17: Furniture & Fittings | C17: 0.1 | D17: 1241453.7 | E17: ='FA Additions'!G30 -> 0 | F17: ='FA Additions'!H30 -> 41450 | G17: 0 | H17: =+D17+E17+F17-G17 -> 1282903.7 | I17: =+((D17+E17-G17)*C17)+(F17*C17/2) -> 126217.87 | K17: =+H17-I17-J17 -> 1156685.8
D18: 60166356 | E18: =SUM(E16:E17) -> 0 | F18: =SUM(F16:F17) -> 41450 | G18: =SUM(G16:G17) -> 0 | H18: =SUM(H16:H17) -> 60207806 | I18: =SUM(I16:I17) -> 6018708.1 | J18: =SUM(J16:J17) -> 0 | K18: =SUM(K16:K17) -> 54189098
B19: BLOCK - III 15%
A20: =+A17+1 -> 4 | B20: Airconditioners | C20: 0.15 | D20: 87917.2 | E20: 0 | F20: 0 | G20: 0 | H20: =+D20+E20+F20-G20 -> 87917.2 | I20: =+((D20+E20)*C20)+(F20*C20/2) -> 13187.58 | K20: =+H20-I20-J20 -> 74729.62
A21: =A20+1 -> 5 | B21: Inventor | C21: 0.15 | D21: 3354.95 | E21: 0 | F21: 0 | G21: 0 | H21: =+D21+E21+F21-G21 -> 3354.95 | I21: =+((D21+E21)*C21)+(F21*C21/2) -> 503.2425 | K21: =+H21-I21-J21 -> 2851.7075
A22: =A21+1 -> 6 | B22: Plant & Machineries | C22: 0.15 | D22: 1.0450414e+08 | E22: ='FA Additions'!G20 -> 528000 | F22: ='FA Additions'!H28 -> 6774500 | G22: ='FA Additions'!F45 -> 1500000 | H22: =+D22+E22+F22-G22 -> 1.1030664e+08 | I22: =+((D22+E22-G22)*C22)+F22*C22/2 -> 16037909 | J22: =(E22*0.2)+F22*0.1 -> 783050 | K22: =+H22-I22-J22 -> 93485685
A23: =A22+1 -> 7 | B23: Telephone | C23: 0.15 | D23: 3269.1 | E23: 0 | F23: 0 | G23: 0 | H23: =+D23+E23+F23-G23 -> 3269.1 | I23: =+((D23+E23)*C23)+(F23*C23/2) -> 490.365 | K23: =+H23-I23-J23 -> 2778.735
A24: =A23+1 -> 8 | B24: Office Equipments | C24: 0.15 | D24: 474775.58 | E24: ='FA Additions'!G35 -> 74067.8 | F24: ='FA Additions'!H35 -> 8515.63 | G24: 0 | H24: =+D24+E24+F24-G24 -> 557359.01 | I24: =+((D24+E24)*C24)+(F24*C24/2) -> 82965.179 | K24: =+H24-I24-J24 -> 474393.83
A25: =A24+1 -> 9 | B25: 2 wheelers | C25: 0.15 | D25: 194786.85 | E25: 0 | F25: 0 | G25: 0 | H25: =+D25+E25+F25-G25 -> 194786.85 | I25: =+((D25+E25)*C25)+(F25*C25/2) -> 29218.028 | K25: =+H25-I25-J25 -> 165568.82
A26: =A25+1 -> 10 | B26: Car | C26: 0.15 | D26: 1224076.5 | F26: ='FA Additions'!H39 -> 785210 | G26: 0 | H26: =+D26+E26+F26-G26 -> 2009286.5 | I26: =+((D26+E26)*C26)+(F26*C26/2) -> 242502.23 | K26: =+H26-I26-J26 -> 1766784.3
A27: =A26+1 -> 11 | B27: Electrical Equipments | C27: 0.15 | D27: 13155912 | E27: 0 | F27: 0 | H27: =+D27+E27+F27-G27 -> 13155912 | I27: =+((D27+E27)*C27)+(F27*C27/2) -> 1973386.9 | K27: =+H27-I27-J27 -> 11182526
A28: =A27+1 -> 12 | B28: Trucks and trailers | C28: 0.15 | D28: 1587519.5 | F28: =SUM('FA Additions'!H37:H38) -> 1350000 | G28: 0 | H28: =+D28+E28+F28-G28 -> 2937519.5 | I28: =+((D28+E28)*C28)+(F28*C28/2) -> 339377.92 | K28: =+H28-I28-J28 -> 2598141.6
D29: =SUM(D20:D28) -> 1.2123576e+08 | E29: =SUM(E20:E28) -> 602067.8 | F29: =SUM(F20:F28) -> 8918225.6 | G29: =SUM(G20:G28) -> 1500000 | H29: =SUM(H20:H28) -> 1.2925605e+08 | I29: =SUM(I20:I28) -> 18719540 | J29: =SUM(J20:J28) -> 783050 | K29: =SUM(K20:K28) -> 1.0975346e+08 | L29: 129256050 | M29: =H29-L29 -> -0.7915
B31: BLOCK - IV 25%
A32: =A28+1 -> 13 | B32: Software | C32: 0.25 | F32: ='FA Additions'!H12 -> 480000 | H32: =+D32+E32+F32-G32 -> 480000 | I32: =+((D32+E32)*C32)+F32*C32/2 -> 60000 | K32: =+H32-I32-J32 -> 420000
D33: =SUM(D32) -> 0 | E33: =SUM(E32) -> 0 | F33: =SUM(F32) -> 480000 | G33: =SUM(G32) -> 0 | H33: =SUM(H32) -> 480000 | I33: =SUM(I32) -> 60000 | J33: =SUM(J32) -> 0 | K33: =SUM(K32) -> 420000
B35: BLOCK - V 40%
A36: =A32+1 -> 14 | B36: Computer & Peripherals | C36: 0.4 | D36: 425358.47 | E36: ='FA Additions'!G18 -> 0 | F36: ='FA Additions'!H18 -> 272838.93 | G36: 0 | H36: =+D36+E36+F36-G36 -> 698197.4 | I36: =+((D36+E36)*C36)+F36*C36/2 -> 224711.17 | K36: =+H36-I36-J36 -> 473486.22
D37: =SUM(D36) -> 425358.47 | E37: =SUM(E36) -> 0 | F37: =SUM(F36) -> 272838.93 | G37: =SUM(G36) -> 0 | H37: =SUM(H36) -> 698197.4 | I37: =SUM(I36) -> 224711.17 | K37: =SUM(K36) -> 473486.22
B39: GRAND TOTAL | D39: =D14+D18+D29+D33+D37 -> 2.0677001e+08 | E39: =E14+E18+E29+E33+E37 -> 602067.8 | F39: =F14+F18+F29+F33+F37 -> 9712514.6 | G39: =G14+G18+G29+G33+G37 -> 1500000 | H39: =H14+H18+H29+H33+H37 -> 2.1558459e+08 | I39: =I14+I18+I29+I33+I37 -> 25022960 | J39: =J14+J18+J29+J33+J37 -> 783050 | K39: =K14+K18+K29+K33+K37 -> 1.8977858e+08
A43: For and on behalf of the Board of Directors of | H43: As per our report of even date
A44: DYNAMIC AIR ENGINEERING INDIA PRIVATE LIMITED | H44: For S.Ravi & Associates
H45: Chartered Accountants
H46: Firm Reg No: 009261S
A49: K. KARTHIKEYAN | D49: GIRIJA KARTHIKEYAN | H49: S.RAVI
A50: DIRECTOR | D50: DIRECTOR | H50: Proprietor
...

Sheet Key Ratios
A1: Ratio | B1: Year ended 31 March, 2022 | C1: Year ended 31 March, 2021 | D1: Variance % | E1: Reasons for Variance (Mandatory if variance is more than 25%)
A2: (a) Current Ratio (in times) | B2: =B3/B4 -> 1.1000644 | C2: =C3/C4 -> 1.1898263 | D2: =(B2-C2)/C2 -> -0.075441188 | F2: Current assets/ current liabilities
A3: - Current Assets | B3: =SUM(BS!G39:G42) -> 225478.21 | C3: =SUM(BS!H39:H42) -> 166046.63
A4: - Current Liabilities | B4: =SUM(BS!G20:G25) -> 204968.2 | C4: =SUM(BS!H20:H25) -> 139555.35
A6: (b) Debt-Equity Ratio (in times) | B6: =(B7-B8)/(B9-B10) -> 2.5632018 | C6: =(C7-C8)/(C9-C10) -> 2.6569655 | D6: =(B6-C6)/C6 -> -0.035289766 | F6: (Total Debt - Cash and cash equivalents)/ (Total equity - Investments in subsidiaries)
A7: - Total Debt | B7: =BS!G15+BS!G20 -> 244102.77 | C7: =BS!H15+BS!H20 -> 225276.52
A8: - Cash & Cash Equivalents | B8: =BS!G41 -> 8673.6364 | C8: =BS!H41 -> 2204.3002
A9: - Shareholders Equity | B9: =SUM(BS!G9:G10) -> 91849.63 | C9: =SUM(BS!H9:H10) -> 83957.515
A10: - Investments in subsidiaries | B10: 0 | C10: 0
A12: (c) Debt Service Coverage Ratio (in times) | B12: =SUM(B13:B14)/SUM(B14:B15) -> 0.60289275 | C12: =SUM(C13:C14)/(C14+C15) -> 0.71850881 | D12: =(B12-C12)/C12 -> -0.16091112 | F12: (Profit before tax + Interest expenses) / (Interest expenses + Repayment of long-term loans during the year)
A13: - Profit before tax | B13: =PL!E18 -> 11220.478 | C13: =PL!F18 -> 3195.779
A14: - Interest expense | B14: =PL!E14 -> 25251.749 | C14: =PL!F14 -> 24227.589
A15: - Repayments made during the year | B15: 35243.633 | C15: 13939.47
A17: (d) Return on Equity Ratio (in %) | B17: =B18/((B19+B20)/2-B21) -> 0.089781509 | C17: =C18/((C19+C20)/2-C21) -> 0.024886143 | D17: =(B17-C17)/C17 -> 2.6076907 | E17: Increase in turnover & Profit | F17: Profit after tax / (Average equity – Investments in subsidiaries)
A18: - Net Profits after taxes – Preference Dividend (if any) | B18: =PL!E31 -> 7892.1153 | C18: =PL!F31 -> 2063.6999
A19: - Opening Shareholder’s Equity | B19: =C20 -> 83957.515 | C19: 81893.81
A20: - Closing Shareholder’s Equity | B20: =SUM(BS!G9:G10) -> 91849.63 | C20: =SUM(BS!H9:H10) -> 83957.515
A21: - Investment in subsidiaries | B21: 0 | C21: 0
A23: (e) Inventory turnover ratio (in times) | B23: =B24/(B25+B26)/2 -> 1.5218004 | C23: =C24/(C25+C26)/2 -> 0.8540187 | D23: =(B23-C23)/C23 -> 0.78192865 | E23: Increase in turnover & Profit | F23: Revenue from operations / Average inventories
A24: - Revenue from operations | B24: =PL!E7 -> 460793.21 | C24: =PL!F7 -> 175821.62
A25: - Closing Inventory | B25: =BS!G39 -> 94501.381 | C25: =BS!H39 -> 56896.007
A26: - Opening Inventory | B26: =C25 -> 56896.007 | C26: 46041.8
A28: (f) Trade Receivables turnover ratio (in times) | B28: =B29/(B30+B31)/2 -> 1.405615 | C28: =C29/(C30+C31)/2 -> 0.70312864 | D28: =(B28-C28)/C28 -> 0.99908649 | E28: Collections made before timeline | F28: Revenue from operations / Average trade receivables
A29: - Revenue from operations | B29: =B24 -> 460793.21 | C29: =C24 -> 175821.62
A30: - Opening Trade Debtors / Accounts receivable | B30: =C31 -> 69214.863 | C30: 55813.2
A31: - Closing Trade Debtors / Accounts receivable | B31: =BS!G40 -> 94696.741 | C31: =BS!H40 -> 69214.863
A33: (g) Trade payables turnover ratio (in times) | B33: =B34/(B35+B36)/2 -> 1.2188625 | C33: =C34/(C35+C36)/2 -> 0.27937795 | D33: =(B33-C33)/C33 -> 3.3627726 | E33: Creditors paid before timeline | F33: Credit Purchases / Average trade payables
A34: - Purchases | B34: =PL!E11+PL!E16 -> 363247.34 | C34: =PL!F11+PL!F16 -> 115110.2
A35: - Opening Trade Payables | B35: =C36 -> 67254.73 | C35: 138756.88
A36: - Closing Trade Payables | B36: =BS!G23 -> 81756.068 | C36: 67254.73
A38: (h) Net capital turnover ratio | B38: =B39/B40 -> 22.466744 | C38: =C39/C40 -> 6.636964 | D38: =(B38-C38)/C38 -> 2.3850935 | E38: Increase in turnover & Profit | F38: Revenue from operations / Average Working Capital
A39: - Revenue from operations | B39: =B29 -> 460793.21 | C39: =C29 -> 175821.62
A40: - Average Working Capital | B40: =B3-B4 -> 20510.013 | C40: =C3-C4 -> 26491.273
A42: (i) Net profit ratio (in %) | B42: =B43/B44 -> 0.024350355 | C42: =C43/C44 -> 0.018176257 | D42: =(B42-C42)/C42 -> 0.33967929 | E42: Increase in turnover & Profit | F42: Net profit / Revenue from operations
A43: - Net profit | B43: =PL!E22 -> 11220.478 | C43: =PL!F22 -> 3195.779
A44: - Revenue from operations | B44: =B39 -> 460793.21 | C44: =C39 -> 175821.62
A46: (j) Return on Capital employed (in %) | B46: =B47/B48 -> 0.53258035 | C46: =C47/C48 -> 0.44155879 | D46: =(B46-C46)/C46 -> 0.20613691 | F46: (Profit before tax + Interest expenses)/( Average capital employed- Cash and Cash Equivalents)
A47: - Earnings Before Interest and tax | B47: =PL!E18+PL!E14 -> 36472.228 | C47: =PL!F18+PL!F14 -> 27423.368
A48: - Average Capital employed | B48: 68482.112 | C48: 62105.814
A50: (k) Return on investment (in %) | B50: NA | C50: NA | D50: 0 | F50: Other Income / Average Cash and Cash Equivalents and Other Marketable Securities)
...

Sheet FA Additions
B1: =+BS!A1 -> DYNAMIC AIR ENGINEERING INDIA PRIVATE LIMITED
B2: =+BS!A2 -> CIN No. : U29192TN2008PTC066303
B3: ='Dep IT'!A4 -> REGISTERED OFFICE
B4: ='Dep IT'!A5 -> NO. 4, BOOPATHY NAGAR, INDUSTRIAL ESTATE
B5: ='Dep IT'!A6 -> KEEZHKATTALAI, CHENNAI - 600 117.
B7: Details of Additions | I7: 44651
B8: SL NO | C8: DESCRIPTION | D8: DATE OF ADDITION | E8: DATE OF PUT TO USE | F8: Amount | G8: BEFORE SEP | H8: AFTER SEP | I8: Check
C10: Software
C11: Solidworks Premium Software | D11: 44501 | E11: 44501 | F11: 480000 | H11: =F11 -> 480000 | I11: =+$I$7-E11+1 -> 151
F12: =SUM(F11) -> 480000 | G12: =SUM(G11) -> 0 | H12: =SUM(H11) -> 480000
C13: Computer & Peripherals
C14: Computer | D14: 44525 | E14: 44525 | F14: 124576.27 | H14: =F14 -> 124576.27 | I14: =+$I$7-E14+1 -> 127
C15: Printer | D15: 44585 | E15: 44585 | F15: 17796.61 | G15: 0 | H15: =F15 -> 17796.61 | I15: =+$I$7-E15+1 -> 67
C16: Computer | D16: 44622 | E16: 44622 | F16: 88983.05 | G16: 0 | H16: =F16 -> 88983.05 | I16: =+$I$7-E16+1 -> 30
C17: Computer | D17: 44628 | E17: 44628 | F17: 41483 | G17: 0 | H17: =F17 -> 41483 | I17: =+$I$7-E17+1 -> 24
F18: =SUM(F14:F17) -> 272838.93 | G18: =SUM(G14:G17) -> 0 | H18: =SUM(H14:H17) -> 272838.93
C19: Plant & Machinery
C20: Welding Machine | D20: 44469 | E20: 44469 | F20: 528000 | G20: =F20 -> 528000
C21: Welding Machine | D21: 44573 | E21: 44573 | F21: 64500 | G21: 0 | H21: =F21 -> 64500 | I21: =+$I$7-E21+1 -> 79
C22: Paint Booth | D22: 44608 | E22: 44608 | F22: 900000 | G22: 0 | H22: =F22 -> 900000 | I22: =+$I$7-E22+1 -> 44
C23: Shot Blast Equipment | D23: 44635 | E23: 44635 | F23: 1700000 | H23: =F23 -> 1700000
C24: Paint Booth Equipment | D24: 44635 | E24: 44635 | F24: 900000 | H24: =F24 -> 900000 | L24: Subsidy-Rs.15,00,000
C25: Industrial Crane | D25: 44646 | E25: 44646 | F25: 2600000 | H25: =F25 -> 2600000
C26: Industrial Crane | D26: 44651 | E26: 44651 | F26: 125000 | H26: =F26 -> 125000
C27: Power Unit | D27: 44651 | E27: 44651 | F27: 485000 | H27: =F27 -> 485000
F28: =SUM(F20:F27) -> 7302500 | G28: =SUM(G20:G27) -> 528000 | H28: =SUM(H20:H27) -> 6774500
C29: Furniture & Fittings
C30: Steel Almirah | D30: 44585 | E30: 44585 | F30: 41450 | G30: 0 | H30: =F30 -> 41450 | I30: =+$I$7-E30+1 -> 67
C32: Office Equipments
C33: Camera & Installation | D33: 44468 | E33: 44468 | F33: 74067.8 | G33: =IF(I33>180,F33,0) -> 74067.8 | H33: =IF(I33>180,0,F33) -> 0 | I33: =+$I$7-E33+1 -> 184
C34: Projector | D34: 44592 | E34: 44592 | F34: 8515.63 | G34: 0 | H34: =F34 -> 8515.63 | I34: =+$I$7-E34+1 -> 60
F35: =SUM(F33:F34) -> 82583.43 | G35: =SUM(G33:G34) -> 74067.8 | H35: =SUM(H33:H34) -> 8515.63
C36: Vehicle
C37: 75 Feet Trailor | D37: 44537 | E37: 44537 | F37: 625000 | G37: =IF(I37>180,F37,0) -> 0 | H37: =IF(I37>180,0,F37) -> 625000 | I37: =+$I$7-E37+1 -> 115
C38: Trailor Jeep | D38: 44537 | E38: 44537 | F38: 725000 | G38: =IF(I38>180,F38,0) -> 0 | H38: =IF(I38>180,0,F38) -> 725000 | I38: =+$I$7-E38+1 -> 115
C39: Maruti Dezire Car | D39: 44562 | E39: 44562 | F39: 785210 | G39: =IF(I39>180,F39,0) -> 0 | H39: =IF(I39>180,0,F39) -> 785210 | I39: =+$I$7-E39+1 -> 90
F40: =SUM(F37:F39) -> 2135210 | G40: =SUM(G37:G39) -> 0 | H40: =SUM(H37:H39) -> 2135210
E43: GROSS TOTAL | F43: =F40+F35+F30+F28+F18+F12 -> 10314582 | G43: =G40+G35+G30+G28+G18+G12 -> 602067.8 | H43: =H40+H35+H30+H28+H18+H12 -> 9712514.6
C45: Subsidy Received | F45: 1500000 | G45: =F45 -> 1500000 | I45: 44355

Sheet BS
A1: DYNAMIC AIR ENGINEERING INDIA PRIVATE LIMITED
A2: CIN No. : U29192TN2008PTC066303
A3: Balance Sheet as at 31st March 2022
A4: (All amounts are in Indian Rupees in thousands, except share data and as stated)
B5: Particulars | F5: Note No. | G5: As at 31st March, 2022 (Current reporting period) | H5: As at 31st March, 2021 (Previous reporting period)
A6: I. | B6: EQUITY AND LIABILITIES
A8: 1 | B8: Shareholders’ funds
B9: (a) | C9: Share capital | F9: 2 | G9: =ROUND('BS Notes'!E18,0)/1000 -> 28500 | H9: =+'BS Notes'!F18/1000 -> 28500 | I9: 28500 | J9: =G9-H9 -> 0
B10: (b) | C10: Reserves and surplus | F10: 3 | G10: ='BS Notes'!E56 -> 63349.63 | H10: ='BS Notes'!F56 -> 55457.515 | I10: =53393814.65/1000 -> 53393.815 | J10: =G10-H10 -> 7892.1153
A12: 2 | B12: Share application money pending allotment | G12: 0 | H12: 0
A14: 3 | B14: Non-current liabilities
B15: (a) | C15: Long-term borrowings | F15: 4 | G15: ='BS Notes'!E70 -> 136398.97 | H15: ='BS Notes'!F70 -> 163379.73 | I15: =147890891.9/1000 -> 147890.89 | J15: =G15-H15 -> -26980.76
B16: (b) | C16: Deferred tax liabilities(net) | F16: 5 | G16: =IF('BS Notes'!E86>0,'BS Notes'!E86,0) -> 2881.4896 | H16: =+'BS Notes'!F86 -> 4666.3069 | J16: =G16-H16 -> -1784.8172
B17: (c) | C17: Long-term provisions | F17: 6 | G17: ='BS Notes'!E92 -> 742.962 | H17: ='BS Notes'!F92 -> 742.962 | J17: =G17-H17 -> 0
A19: 4 | B19: Current liabilities
B20: (a) | C20: Short-term borrowings | F20: 7 | G20: =+'BS Notes'!E111 -> 107703.8 | H20: =+'BS Notes'!F111 -> 61896.787 | I20: =29555080.5/1000 -> 29555.081 | J20: =G20-H20 -> 45807.014 | K20: =G15+G20 -> 244102.77 | L20: =H15+H20 -> 225276.52 | M20: =(I15+I20) -> 177445.97 | N20: =M20-L20 -> -47830.548
B21: (b) | C21: Trade payables | F21: 8
C22: (A) Total outstanding dues of micro enterprises and small enterprises
C23: (B) Total outstanding dues of creditors other than Micro enterprises and small enterprises | G23: ='BS Notes'!E123 -> 81756.068 | H23: ='BS Notes'!F123 -> 67254.733 | J23: =G23-H23 -> 14501.335
B24: (c) | C24: Other current liabilities | F24: 9 | G24: ='BS Notes'!E158 -> 10398.22 | H24: ='BS Notes'!F158 -> 7183.0632 | J24: =G24-H24 -> 3215.1568
B25: (d) | C25: Short-term provisions | F25: 10 | G25: ='BS Notes'!E179 -> 5110.11 | H25: =3220770/1000 -> 3220.77 | J25: =G25-H25 -> 1889.34
D26: TOTAL | G26: =SUM(G8:G25) -> 436841.25 | H26: =SUM(H8:H25) -> 392301.87
A27: II. | B27: ASSETS
B28: Non-current assets
A29: 1 | B29: (a) | C29: Property, Plant and Equipment and Intangible Assets | F29: 11
C30: (i) | D30: Property, Plant and Equipment | G30: ='Dep - co'!M26-G31 -> 200524.58 | H30: =+'Dep - co'!L26 -> 224286.18 | J30: =G30-H30 -> -23761.598
C31: (ii) | D31: Intangible assets | G31: ='Dep - co'!M24 -> 354.58044 | H31: 0 | J31: =G31-H31 -> 354.58044
C32: (iii) | D32: Capital work-in-progress | G32: =+'Dep - co'!G36 -> 0 | H32: =+'Dep - co'!L36 -> 0
C33: (iv) | D33: Intangible assets under development | G33: 0 | H33: 0
B34: (b) | C34: Non-current investments | G34: 0 | H34: 0
B35: (c) | C35: Deferred tax Assets (net) | G35: 0 | H35: 0
B36: (d) | C36: Other non-current assets | F36: 12 | G36: ='BS Notes'!E189 -> 10483.879 | H36: ='BS Notes'!F189 -> 1969.063 | J36: =G36-H36 -> 8514.816
A38: 2 | B38: Current assets
B39: (a) | C39: Inventories | F39: 13 | G39: ='BS Notes'!E199 -> 94501.381 | H39: ='BS Notes'!F199 -> 56896.007 | J39: =G39-H39 -> 37605.374
B40: (b) | C40: Trade receivables | F40: 14 | G40: =+'BS Notes'!E207 -> 94696.741 | H40: =+'BS Notes'!F207 -> 69214.863 | J40: =G40-H40 -> 25481.879
B41: (c) | C41: Cash and cash equivalents | F41: 15 | G41: ='BS Notes'!E238 -> 8673.6364 | H41: ='BS Notes'!F238 -> 2204.3002 | J41: =G41-H41 -> 6469.3362
B42: (d) | C42: Other current assets | F42: 16 | G42: ='BS Notes'!E260 -> 27606.452 | H42: ='BS Notes'!F260 -> 37731.456 | J42: =G42-H42 -> -10125.004
K43: =J43+G43 -> 0
D44: TOTAL | G44: =SUM(G29:G43) -> 436841.25 | H44: =SUM(H29:H43) -> 392301.87 | J44: =G44-G26 -> 1.617067e-06 | K44: =H44-H26 -> 1.617067e-06
A45: Summary of Significant Accounting Policies | F45: 1
...

Sheet PL
A1: DYNAMIC AIR ENGINEERING INDIA PRIVATE LIMITED
A2: CIN No. : U29192TN2008PTC066303
A3: Statement of Profit And Loss for the Year Ended 31st March 2022
A4: =BS!A4 -> (All amounts are in Indian Rupees in thousands, except share data and as stated)
B5: Particulars | D5: Note No. | E5: For the year ended 31st March, 2022 | F5: For the year ended 31st March, 2021 | I5: 2021-2022 | J5: 2020-2021
H6: Sales | I6: =E7 -> 460793.21 | J6: =F7 -> 175821.62
A7: I. | B7: Revenue from operations | D7: 17 | E7: ='PL Notes'!C15 -> 460793.21 | F7: ='PL Notes'!D15 -> 175821.62 | G7: ='Link Sheet'!F443 -> -460793.21 | H7: Cost of Sales | I7: =SUM(E11:E12) -> 352325.79 | J7: =SUM(F11:F12) -> 97566.643
A8: II. | B8: Other income | D8: 18 | E8: ='PL Notes'!C24 -> 728.57951 | F8: ='PL Notes'!D24 -> 176.674 | G8: ='Link Sheet'!F452 -> -728.57951 | H8: GP | I8: =I6-I7 -> 108467.41 | J8: =J6-J7 -> 78254.981
A9: III. | B9: Total Income (I + II) | E9: =+E7+E8 -> 461521.79 | F9: =+F7+F8 -> 175998.3 | I9: =I8/I6*100 -> 23.539282 | J9: =J8/J6*100 -> 44.508166
A10: IV. | B10: Expenses: | H10: NP | I10: =E18/E7*100 -> 2.4350355 | J10: =F18/F7*100 -> 1.8176257
B11: Raw Materials Consumed & Direct Costs | D11: 19 | E11: ='PL Notes'!C36 -> 343545.92 | F11: ='PL Notes'!D36 -> 106233.88 | G11: ='Link Sheet'!F490 -> 342817.34
B12: Changes in inventories of WIP, Finished goods and Stock-in-Trade | D12: 20 | E12: ='PL Notes'!C50 -> 8779.873 | F12: ='PL Notes'!D50 -> -8667.233 | G12: ='Link Sheet'!F500 -> -36282.081
B13: Employee benefits expense | D13: 21 | E13: ='PL Notes'!C63 -> 20800.743 | F13: ='PL Notes'!D63 -> 3061.2609 | G13: ='Link Sheet'!F516 -> 20800.743
B14: Finance costs | D14: 22 | E14: =+'PL Notes'!C74 -> 25251.749 | F14: =+'PL Notes'!D74 -> 24227.589 | G14: ='Link Sheet'!F539 -> 25251.749
B15: Depreciation and amortization expense | D15: 11 | E15: ='Dep - co'!I26 -> 32221.6 | F15: =39070696.8332249/1000 -> 39070.697
B16: Other expenses | D16: 23 | E16: =+'PL Notes'!C103 -> 19701.422 | F16: =+'PL Notes'!D103 -> 8876.3289 | G16: ='Link Sheet'!F619 -> 19701.422 | K16: Deferred Tax Reco
B17: Total expenses | E17: =SUM(E11:E16) -> 450301.31 | F17: =SUM(F11:F16) -> 172802.52 | K17: Tax rate | L17: =+'Def Tax'!C11 -> 0.2782
A18: V. | B18: Profit before exceptional and extraordinary items and tax (III-IV) | E18: =E9-E17 -> 11220.478 | F18: =F9-F17 -> 3195.779 | G18: 11220478 | K18: NP | L18: =+E22 -> 11220.478
A19: VI. | B19: Exceptional items | E19: 0 | F19: 0 | G19: =G18-E18 -> 11209258 | K19: Tax on NP | N19: =+L17*L18 -> 3121.537
A20: VII. | B20: Profit before extraordinary items and tax (V - VI) | E20: =E18-E19 -> 11220.478 | F20: =F18-F19 -> 3195.779 | K20: Provision for tax + deferred tax | N20: =E24+E25+E26 -> 3328.3628
A21: VIII. | B21: Extraordinary Items | E21: 0 | F21: 0 | K21: Increase in Depreciation as per IT Act | N21: =-('STI '!E30-'STI '!E23)*L17 -> 1784817.2
A22: IX. | B22: Profit before tax (VII- VIII) | E22: =+E20-E21 -> 11220.478 | F22: =+F20-F21 -> 3195.779 | N22: =+N19-N20+N21 -> 1784610.4
A23: X | B23: Tax expense: | K23: Permanent Diff
B24: (1) Current tax | E24: =('STI '!F50+3070)/1000 -> 5113.18 | F24: =3220770/1000 -> 3220.77 | K24: Interest on Delayed Pmt of taxes | L24: =+'STI '!E26 -> 228752.08 | M24: =+L24*$L$17 -> 63638.828
B25: (2) Less: MAT Credit Entitlement | E25: =0 -> 0 | F25: 0 | L25: 279914 | M25: =+L25*$L$17 -> 77872.075
B26: (3) Deferred tax Liability / (Asset) | E26: =-'Def Tax'!C35/1000 -> -1784.8172 | F26: =-2088690.91855138/1000 -> -2088.6909 | K26: =+'STI '!C25 -> Disallowance u/s 36(1)(va) | L26: =+'STI '!E25 -> 3212 | M26: =+L26*$L$17 -> 893.5784
A27: XI | B27: Profit (Loss) for the period from continuing operations (VII-VIII) | E27: =+E22-SUM(E24:E26) -> 7892.1153 | F27: =+F22-SUM(F24:F26) -> 2063.6999 | K27: Term Loan Interest | L27: =SUM('STI '!E28:E28) -> 266229 | M27: =L27*L17 -> 74064.908
A28: XII | B28: Profit/(loss) from discontinuing operations | E28: 0 | F28: 0
A29: XIII | B29: Tax expense of discontinuing operations | E29: 0 | F29: 0 | K29: Disallowance 40(a)(ia) | L29: =+'STI '!E24 -> 0 | M29: =+L29*L17 -> 0 | N29: =SUM(M23:M29) -> 216469.39
A30: XIV | B30: Profit/(loss) from Discontinuing operations (after tax) (XII-XIII) | E30: =E28-E29 -> 0 | F30: 0 | M30: Diff | N30: =+N22+N29 -> 2001079.8
A31: XV | B31: Profit (Loss) for the period (XI + XIV) | E31: =+E27+E30 -> 7892.1153 | F31: =+F27+F30 -> 2063.6999 | H31: =E31*1000 -> 7892115.3
A32: XVI | B32: Earnings per equity share: | K32: CHECK
B33: (1) Basic | E33: =E31/'BS Notes'!C29 -> 2.7691633 | F33: =F31/'BS Notes'!C29 -> 0.72410523 | K33: Profit as per Tally | L33: 14621823
B34: (2) Diluted | E34: =E33 -> 2.7691633 | F34: =F33 -> 0.72410523 | K34: Profit as per Financials | L34: =+E22 -> 11220.478
A35: Summary of Significant Accouting Policies | D35: 1 | K35: Diff | L35: =+L33-L34 -> 14610603
A36: The accompanying notes are an integral part of the finacial statements | E36: As per our report of even date | L36: 0
E37: For S.Ravi & Associates
A38: For and on behalf of the Board of Directors of | E38: Chartered Accountants
A39: DYNAMIC AIR ENGINEERING INDIA PRIVATE LIMITED | E39: Firm Reg No: 009261S
A43: K. KARTHIKEYAN | C43: GIRIJA KARTHIKEYAN | E43: S.RAVI
...

Sheet BS Notes
A1: DYNAMIC AIR ENGINEERING INDIA PRIVATE LIMITED
A2: CIN No. : U29192TN2008PTC066303
A3: NOTES TO THE FINANCIAL STATEMENTS FOR THE YEAR ENDED 31 MARCH 2022
A4: =CFS!A5 -> (All amounts are in Indian Rupees in thousands, except share data and as stated)
A6: Note 2
A7: Share capital
A8: Particulars | E8: As at | F8: As at
E9: 44651 | F9: 44286
A11: Authorised
A12: 65,00,000 Equity Shares of Rs 10 each | E12: =(6500000*10) -> 65000000 | F12: =(6500000*10) -> 65000000
A13: Issued
A14: 28,50,000 Equity Shares of Rs 10 each | E14: =D29 -> 28500000 | F14: =28500*1000 -> 28500000
A15: Subscribed & Paid up
A16: 28,50,000 Equity Shares of Rs. 10 each fully paid | E16: =D29 -> 28500000 | F16: =F14 -> 28500000
A18: Total | E18: =SUM(E16:E17) -> 28500000 | F18: =SUM(F16:F17) -> 28500000
A20: Rights, preferences and restrictions attached to shares
A21: Equity shares: The Company has one class of equity shares having a par value of Rs 10 per share. Each shareholder is eligible for one vote per share held. In the event of liquidation, the equity shareholders are eligible to receive the remaining assets of the Company after distribution of all preferential amounts, in proportion to their shareholding. The dividend proposed by the Board of Directors is subject to the approval of the shareholders in the ensuing Annual General Meeting, except in case of interim dividend
A23: Reconciliation of the number of shares outstanding at the beginning and at the end of the reporting period
A24: Particulars | C24: As at March 31, 2022 | E24: As at March 31, 2021
C25: Number | D25: Amount | E25: Number | F25: Amount
A26: Shares outstanding at the beginning of the year | C26: =+E29 -> 2850 | D26: =+C26*10000 -> 28500000 | E26: 2850 | F26: =28500*1000 -> 28500000
A27: Shares Issued during the year | E27: 0 | F27: 0
A28: Shares bought back during the year | C28: 0 | D28: =+C28*10 -> 0 | E28: 0 | F28: 0
A29: Shares outstanding at the end of the year | C29: =C26+C27-C28 -> 2850 | D29: =D26+D27-D28 -> 28500000 | E29: 2850 | F29: =SUM(F26:F28) -> 28500000
A31: Shares in the company held by each shareholder holding more than 5 percent shares
A32: Name of Shareholder | C32: =C24 -> As at March 31, 2022 | E32: =E24 -> As at March 31, 2021
C33: No. of Shares held | D33: % of Holding | E33: No. of Shares held | F33: % of Holding
A34: K . KARTHIKEYAN | C34: =(145000+145000*6+1746000)/1000 -> 2761 | D34: =+C34/C29 -> 0.96877193 | E34: 2761 | F34: =+E34/E29 -> 0.96877193
A35: GIRIJA KARTHIKEYAN | C35: =(5000+5000*6+54000)/1000 -> 89 | D35: =+C35/C29 -> 0.03122807 | E35: 89 | F35: =+E35/E29 -> 0.03122807
A36: Total | C36: =SUM(C34:C35) -> 2850 | D36: =SUM(D34:D35) -> 1 | E36: =SUM(E34:E35) -> 2850 | F36: =SUM(F34:F35) -> 1
A38: Shares held by promoters at the end of the year
A39: Promoter name | B39: No of Shares | C39: % of Total shares | D39: No of Shares | E39: % of Total shares | F39: % change during the year
A40: K . KARTHIKEYAN | B40: =C34 -> 2761 | C40: =B40/B42 -> 0.96877193 | D40: =(145000+145000*6+1746000)/1000 -> 2761 | E40: =D40/D42 -> 0.96877193 | F40: -
A41: GIRIJA KARTHIKEYAN | B41: =C35 -> 89 | C41: =B41/B42 -> 0.03122807 | D41: =(5000+5000*6+54000)/1000 -> 89 | E41: =D41/D42 -> 0.03122807 | F41: -
A42: TOTAL | B42: =SUM(B40:B41) -> 2850 | C42: =SUM(C40:C41) -> 1 | D42: =SUM(D40:D41) -> 2850 | E42: =SUM(E40:E41) -> 1 | F42: =SUM(F40:F41) -> 0
A44: Note 3
A45: Reserves and surplus
A46: Particulars | E46: =C32 -> As at March 31, 2022 | F46: =E32 -> As at March 31, 2021
A48: Share Premium | D48: a | E48: ='Link Sheet'!C8 -> 16200 | F48: 16200
A50: Surplus
...

Sheet PL Notes
B1: DYNAMIC AIR ENGINEERING INDIA PRIVATE LIMITED
B2: CIN No. : U29192TN2008PTC066303
B3: NOTES TO THE FINANCIAL STATEMENTS FOR THE YEAR ENDED 31 MARCH 2022
B4: =CFS!A5 -> (All amounts are in Indian Rupees in thousands, except share data and as stated)
B6: Note 17
B7: Revenue from operations
B8: Particulars | C8: For the year ended 31 March, 2022 | D8: For the year ended 31 March, 2021
B10: Sales | C10: =-SUM('Link Sheet'!D432:D435) -> 452531.78 | D10: =171696.54122 -> 171696.54 | E10: Excise Duty | G10: 4539462 | I10: =C10-#REF!+C12 -> #REF!
B11: Freight Charges | C11: =-SUM('Link Sheet'!D437:D438) -> 2570.4995 | D11: 914.80468
B12: Packing and Installation | C12: =-SUM('Link Sheet'!D440:D441) -> 40.56741 | D12: 71.60997 | E12: =3145486+62909+31454 -> 3239849
B13: Job Work Income | C13: ='Link Sheet'!C443 -> 5650.3579 | D13: 3138.6674
B15: Total | C15: =SUM(C10:C13) -> 460793.21 | D15: =SUM(D10:D13) -> 175821.62 | E15: 3464166
E16: 42028.68
B17: Note 18 | E17: =SUM(E13:E16) -> 3506194.7
B18: Other income
B19: Particulars | C19: =+$C$8 -> For the year ended 31 March, 2022 | D19: =+$D$8 -> For the year ended 31 March, 2021
B21: Interest on deposits | C21: =SUM('Link Sheet'!C447:C448) -> 391.314 | D21: 144.786
B22: Other income | C22: =-SUM('Link Sheet'!D450:D452) -> 337.26551 | D22: 31.888 | F22: =16577078.86-#REF! -> #REF!
B24: Total | C24: =SUM(C21:C22) -> 728.57951 | D24: =SUM(D21:D22) -> 176.674
B26: Note 19
B27: Cost of materials consumed & Direct expenses
B28: Particulars | C28: =+$C$8 -> For the year ended 31 March, 2022 | D28: =+$D$8 -> For the year ended 31 March, 2021
B30: Raw Materials Consumed & Direct expenses | C30: =SUM('Link Sheet'!D456:D468) -> 298996.88 | D30: 78332.979 | E30: =C30+C31 -> 300805.81
B31: Carriage Inwards | C31: =SUM('Link Sheet'!D471:D474) -> 1808.927 | D31: 732.88698
B32: Rent - Factory | C32: =SUM('Link Sheet'!D476:D477) -> 1498.5 | D32: 1868.25
B33: Electricity & Power | C33: =SUM('Link Sheet'!D479:D480) -> 6722.766 | D33: 4763.079
B34: Wages & Other Direct Expenses | C34: =SUM('Link Sheet'!D482:D490) -> 34518.849 | D34: 20536.681
B36: Total | C36: =SUM(C30:C34) -> 343545.92 | D36: =SUM(D30:D34) -> 106233.88
B38: Note 20
B39: Changes in inventories of finished goods, work-in-progress and stock in Trade
B40: Particulars | C40: =+$C$8 -> For the year ended 31 March, 2022 | D40: =+$D$8 -> For the year ended 31 March, 2021
B42: Opening Stock :
B43: Work-in-Process | C43: =+D47 -> 9882.053 | D43: 13369.828
B44: Finished Goods | C44: =D48 -> 35225.008 | D44: 23070
B46: Closing Stock :
B47: Work-in-Progress | C47: ='BS Notes'!E196 -> 25014.138 | D47: 9882.053
B48: Finished Goods | C48: ='BS Notes'!E197 -> 11313.05 | D48: 35225.008
B50: Decrease / (Increase) in Inventories | C50: =SUM(C43:C44)-SUM(C47:C49) -> 8779.873 | D50: =SUM(D43:D44)-SUM(D47:D49) -> -8667.233
B53: Note 21
B54: Employee Benefits Expense
...

Sheet CFS
A2: =BS!A1 -> DYNAMIC AIR ENGINEERING INDIA PRIVATE LIMITED
A3: =BS!A2 -> CIN No. : U29192TN2008PTC066303
A4: STATEMENT OF CASH FLOW FOR THE YEAR ENDED 31ST MARCH 2022 | G4: BALANCE SHEET AS AT 31ST MARCH 2022
A5: =BS!A4 -> (All amounts are in Indian Rupees in thousands, except share data and as stated)
B6: Particulars | D6: For the year ended 31st March, 2022 | E6: For the year ended 31st March, 2021
A7: A | B7: CASH FLOW FROM OPERATING ACTIVITIES
B8: Profit before tax from continuing operations | D8: =PL!E18 -> 11220.478 | E8: 3195.779
B9: Profit before tax from discontinuing operations | E9: 0
B10: Profit before tax | D10: =SUM(D8:D9) -> 11220.478 | E10: =SUM(E8:E9) -> 3195.779
B11: Non-cash adjustment to reconcile profit before tax to net cash flows | D11: 0 | E11: 0
B12: Share of (profit)/loss from investment in partnership firm | D12: 0 | E12: 0 | F12: 1000
B13: Depreciation/amortization on continuing operation | D13: =PL!E15 -> 32221.6 | E13: 39070.697
B14: Depreciation/amortization on discontinuing operation | D14: 0 | E14: 0
B15: Impairment/other write off on tangible/intangible assets pertaining to continuing operation | D15: 0 | E15: 0
B16: Impairment/other write off on tangible/intangible assets pertaining to discontinued operation | D16: 0 | E16: 0
B17: Loss/(profit) on sale of fixed assets | D17: 0 | E17: 0
B18: Provision for diminution in value of investments in subsidiary company | D18: 0 | E18: 0
B19: Provision for diminution in value of investments (current plus other long term) | D19: 0 | E19: 0
B20: Employee stock compensation expense | D20: 0 | E20: 0
B21: Unrealized foreign exchange loss | D21: 0 | E21: 0
B22: Premium on forward exchange contract amortized | D22: 0 | E22: 0
B23: Amortization of ancillary cost | D23: 0 | E23: 0
B24: Net gain on sale of current investments | D24: 0 | E24: 0
B25: Interest expense | D25: =PL!E14 -> 25251.749 | E25: 24227.589
B26: Preliminary expenses written off | D26: 0 | E26: 0
B27: Interest income | D27: =-'PL Notes'!C21 -> -391.314 | E27: -144.786
B28: Dividend income | D28: 0 | E28: 0
B29: Operating profit before working capital changes | D29: =SUM(D10:D28) -> 68302.514 | E29: =SUM(E10:E28) -> 66349.279
B31: Movements in working capital :
B32: Increase/(decrease) in trade payables | D32: =BS!G23-BS!H23 -> 14501.335 | E32: -71502.144
B33: Increase / (decrease) in long-term provisions | D33: =BS!G17-BS!H17 -> 0 | E33: 0
B34: Increase / (decrease) in short-term provisions | D34: 0 | E34: 0
B35: Increase/(decrease) in other current liabilities | D35: =BS!G24-BS!H24 -> 3215.1568 | E35: -1020.6692
B36: Increase/ (decrease) in other long-term liabilities | D36: 0 | E36: 0
B37: Increase/ (decrease) in short term provision | D37: =-PL!E25 -> 0 | E37: 0
B38: Decrease/(increase) in trade receivables | D38: =BS!H40-BS!G40 -> -25481.879 | E38: -13401.662
B39: Decrease/(increase) in inventories | D39: =BS!H39-BS!G39 -> -37605.374 | E39: -10854.209
B40: Decrease / (increase) in long-term loans and advances | D40: =BS!H36-BS!G36 -> -8514.816 | E40: 0
B41: Decrease / (increase) in short-term loans and advances | D41: =BS!H42-BS!G42 -> 10125.004 | E41: 37004.588
B42: Decrease/(increase) in other current assets | D42: 0 | E42: 0
...

Sheet Dep - co
A1: DYNAMIC AIR ENGINEERING INDIA PRIVATE LIMITED
A2: CIN No. : U29192TN2008PTC066303
A3: ='PL Notes'!B3 -> NOTES TO THE FINANCIAL STATEMENTS FOR THE YEAR ENDED 31 MARCH 2022
A5: Note 11 - Property, Plant & Equipment and Intangible Assets
A6: =CFS!A5 -> (All amounts are in Indian Rupees in thousands, except share data and as stated)
B7: Fixed Assets | D7: Gross Block | H7: Accumulated Depreciation | L7: Net Block
D8: Balance as at 31 March 2021 | E8: Additions/ (Disposals) | F8: Subsidy received | G8: Balance as at 31 March 2022 | H8: =D8 -> Balance as at 31 March 2021 | I8: Depreciation for the year | J8: Subsidy received | K8: =G8 -> Balance as at 31 March 2022 | L8: =H8 -> Balance as at 31 March 2021 | M8: =K8 -> Balance as at 31 March 2022
A9: I | B9: Property, Plant & Equipment
A11: a | B11: Land | C11: 0 | D11: 24942.539 | E11: 0 | F11: 0 | G11: =SUM(D11:F11) -> 24942.539 | H11: 0 | I11: 0 | J11: 0 | K11: =SUM(H11:J11) -> 0 | L11: 24942.539 | M11: =+G11-K11 -> 24942.539
A12: b | B12: Factory Building | C12: 0.1 | D12: 82773.607 | E12: 0 | F12: 0 | G12: =SUM(D12:F12) -> 82773.607 | H12: 22264.801 | I12: =('FA Register'!BS59)/1000 -> 5747.5527 | J12: 0 | K12: =SUM(H12:J12) -> 28012.353 | L12: =+D12-H12 -> 60508.807 | M12: =+G12-K12 -> 54761.254 | N12: ='FA Register'!BT59 -> 54761255 | O12: =M12-N12 -> -54706494
A13: c | B13: Computers & Peripherals | C13: 0.4 | D13: =(1400345.65)/1000 -> 1400.3456 | E13: =('FA Additions'!F18)/1000 -> 272.83893 | F13: 0 | G13: =SUM(D13:F13) -> 1673.1846 | H13: 1129.4034 | I13: =('FA Register'!BS95/1000-I24) -> 190.29025 | J13: 0 | K13: =SUM(H13:J13) -> 1319.6936 | L13: =+D13-H13 -> 270.94227 | M13: =+G13-K13 -> 353.49095 | N13: ='FA Register'!BT95-'FA Register'!BT93 -> 353490.26 | O13: =M13-N13 -> -353136.77
A14: d | B14: Air Conditioners | C14: 0.1391 | D14: 199.784 | E14: 0 | F14: 0 | G14: =SUM(D14:F14) -> 199.784 | H14: 131.83882 | I14: =(SUM('FA Register'!BS97:BS102))/1000 -> 52.946854 | J14: 0 | K14: =SUM(H14:J14) -> 184.78567 | L14: =+D14-H14 -> 67.945181 | M14: =+G14-K14 -> 14.998326 | N14: =SUM('FA Register'!BT97:BT102) -> 14998.05 | O14: =M14-N14 -> -14983.052
A15: e | B15: Plant & Machineries | C15: 0.1391 | D15: 206210.07 | E15: =('FA Additions'!F28)/1000 -> 7302.5 | F15: =('FA Additions'!F45)/1000 -> 1500 | G15: =SUM(D15:E15)-F15 -> 212012.57 | H15: 79634.74 | I15: =('FA Register'!BS301)/1000 -> 22748.461 | J15: 0 | K15: =SUM(H15:J15)+13767 -> 116150.2 | L15: =+D15-H15 -> 126575.33 | M15: =+G15-K15 -> 95862.365 | N15: ='FA Register'!BT301 -> 1.0961479e+08 | O15: =M15-N15 -> -1.0951893e+08
A16: f | B16: Invertor | C16: 0.1391 | D16: 25.5 | E16: 0 | F16: 0 | G16: =SUM(D16:F16) -> 25.5 | H16: 23.709111 | I16: =('FA Register'!BS104)/1000 -> 0.51515904 | J16: 0 | K16: =SUM(H16:J16) -> 24.22427 | L16: =+D16-H16 -> 1.790889 | M16: =+G16-K16 -> 1.27573 | N16: ='FA Register'!BT104 -> 1275 | O16: =M16-N16 -> -1273.7243
A17: g | B17: Telephone Instruments | C17: 0.1391 | D17: 20.948 | E17: 0 | F17: 0 | G17: =SUM(D17:F17) -> 20.948 | H17: 20.546226 | I17: =(SUM('FA Register'!BS106:BS110))/1000 -> 0 | J17: 0 | K17: =SUM(H17:J17) -> 20.546226 | L17: =+D17-H17 -> 0.4017736 | M17: =+G17-K17 -> 0.4017736 | N17: ='FA Register'!BT106+'FA Register'!BT107+'FA Register'!BT108+'FA Register'!BT109+'FA Register'!BT110 -> 401.77219 | O17: =M17-N17 -> -401.37042
A18: h | B18: Office Equipments | C18: 0.1391 | D18: 768.84622 | E18: =('FA Additions'!F35)/1000 -> 82.58343 | F18: 0 | G18: =SUM(D18:F18) -> 851.42965 | H18: 480.04158 | I18: =(SUM('FA Register'!BS112:BS131))/1000 -> 175.97503 | J18: 0 | K18: =SUM(H18:J18)-13767 -> -13110.983 | L18: =+D18-H18 -> 288.80464 | M18: =+G18-K18 -> 13962.413 | N18: =SUM('FA Register'!BT112:BT132) -> 209180.11 | O18: =M18-N18 -> -195217.7
A19: i | B19: Vehicles | C19: 0.2589 | D19: 7298.3147 | E19: =('FA Additions'!F40)/1000 -> 2135.21 | F19: 0 | G19: =SUM(D19:F19) -> 9433.5247 | H19: 5872.3232 | I19: =('FA Register'!BS158)/1000 -> 537.10015 | J19: 0 | K19: =SUM(H19:J19) -> 6409.4234 | L19: =+D19-H19 -> 1425.9915 | M19: =+G19-K19 -> 3024.1013 | N19: ='FA Register'!BT158 -> 3024099.5 | O19: =M19-N19 -> -3021075.4
A20: j | B20: Electrical Installations | D20: 19682.887 | E20: 0 | F20: 0 | G20: =SUM(D20:F20) -> 19682.887 | H20: 10263.618 | I20: =('FA Register'!BS138)/1000 -> 2438.324 | J20: 0 | K20: =SUM(H20:J20) -> 12701.942 | L20: =+D20-H20 -> 9419.269 | M20: =+G20-K20 -> 6980.945 | N20: ='FA Register'!BT138 -> 6980945 | O20: =M20-N20 -> -6973964
A21: k | B21: Furniture & Fixtures | D21: 1677.3565 | E21: =('FA Additions'!F30)/1000 -> 41.45 | F21: 0 | G21: =SUM(D21:F21) -> 1718.8065 | H21: 892.9922 | I21: =('FA Register'!BS330)/1000 -> 205.0155 | J21: 0 | K21: =SUM(H21:J21) -> 1098.0077 | L21: =+D21-H21 -> 784.36427 | M21: =+G21-K21 -> 620.79877 | N21: ='FA Register'!BT330 -> 620798.77 | O21: =M21-N21 -> -620177.98
O22: =M22-N22 -> 0
A23: II | B23: Intangible Assets | O23: =M23-N23 -> 0
A24: a | B24: Software | E24: =('FA Additions'!F12)/1000 -> 480 | G24: =SUM(D24:F24) -> 480 | H24: 0 | I24: =('FA Register'!BS93)/1000 -> 125.41956 | K24: =SUM(H24:J24) -> 125.41956 | L24: =+D24-H24 -> 0 | M24: =+G24-K24 -> 354.58044 | N24: ='FA Register'!BT93 -> 354580.44 | O24: =M24-N24 -> -354225.86
O25: =SUM(O12:O24) -> -1.7575988e+08
B26: Total | D26: =SUM(D11:D24) -> 345000.2 | E26: =SUM(E11:E24) -> 10314.582 | F26: =SUM(F11:F24) -> 1500 | G26: =SUM(G11:G24) -> 353814.78 | H26: =SUM(H11:H24) -> 120714.01 | I26: =SUM(I11:I24) -> 32221.6 | J26: =SUM(J11:J24) -> 0 | K26: =SUM(K11:K24) -> 152935.61 | ... M26: =SUM(M11:M24) -> 200879.16
A28: II | B28: Intangible Assets
B30: Total | D30: 0 | E30: 0 | F30: 0 | G30: 0 | H30: 0 | I30: 0 | J30: 0 | K30: 0 | L30: 0 | M30: 0
A31: III | B31: Capital Work In Progress
A32: a | B32: Land | F32: 0 | G32: =SUM(D32:F32) -> 0 | H32: 0 | I32: 0 | J32: 0 | K32: 0 | L32: =+D32-H32 -> 0 | M32: =+G32-K32 -> 0
A33: b | B33: Building | F33: 0 | G33: =SUM(D33:F33) -> 0 | H33: 0 | I33: 0 | J33: 0 | K33: 0 | L33: =+D33-H33 -> 0 | M33: =+G33-K33 -> 0
A34: c | B34: Plant and Machinery | F34: 0 | G34: =SUM(D34:F34) -> 0 | H34: 0 | I34: 0 | J34: 0 | K34: 0 | L34: =+D34-H34 -> 0 | M34: =+G34-K34 -> 0
B36: Total | D36: =SUM(D30:D35) -> 0 | E36: =SUM(E30:E35) -> 0 | F36: =SUM(F30:F35) -> 0 | G36: =SUM(G30:G35) -> 0 | H36: =SUM(H30:H35) -> 0 | I36: =SUM(I30:I35) -> 0 | J36: =SUM(J30:J35) -> 0 | K36: =SUM(K30:K35) -> 0 | L36: =SUM(L30:L35) -> 0 | M36: =SUM(M31:M35) -> 0
L39: As per our report of even date
A40: For and on behalf of the Board ofDirectors of | L40: For S.Ravi & Associates
A41: DYNAMIC AIR ENGINEERING INDIA PRIVATE LIMITED | L41: Chartered Accountants
L42: Firm Reg No: 009261S
A46: K . KARTHIKEYAN | D46: GIRIJA KARTHIKEYAN | L46: S.RAVI
A47: Director | D47: Director | L47: Proprietor
A48: DIN : 01924065 | D48: DIN : 03329379 | L48: M No: 204618
A50: PLACE: CHENNAI
A51: =+PL!A48 -> DATE: 02-09-2022

Sheet Def Tax
A1: ='Dep - co'!A1 -> DYNAMIC AIR ENGINEERING INDIA PRIVATE LIMITED
A2: ='Dep - co'!A2 -> CIN No. : U29192TN2008PTC066303
A3: DEFERRED TAX CALCULATION
B4: Schedule for Deferred Tax for the year ended 31.03.22
C5: 31st Mar 22 | D5: 31st Mar 21
B7: Income Tax Rate | C7: 0.25 | D7: 0.25
B8: Surcharge | C8: =+IF('STI '!F41>10000000,C7*7%,0) -> 0.0175 | D8: 0
B9: Education cess @ 4% | C9: 0 | D9: 0
B10: Health and education cess @ 4% | C10: =+(C7+C8)*4% -> 0.0107 | D10: 0.01
B11: TOTAL | C11: =SUM(C7:C10) -> 0.2782 | D11: =SUM(D7:D10) -> 0.26
B13: Deferred tax Asset / Liability arising on account of
A15: 1 | B15: Block of Assets | F15: 16644174 | G15: =F15*D11 -> 4327485.2
B16: Closing WDV of Assets as at yearend - as per Income Tax Act | C16: ='Dep IT'!K39 -> 1.8977858e+08
B17: Closing WDV of Assets as at yearend - as per Books | C17: ='Dep - co'!M26*1000 -> 2.0087916e+08
B18: Timing Difference on account of Closing WDV | C18: =+C16-C17 -> -11100581 | D18: =+C18*C11 -> -3088181.7 | E18: DTA / (DTL)
A20: 2 | B20: Others
B21: On account of Gratuity provision | C21: =BS!G17*1000 -> 742962 | D21: =C21*C11 -> 206692.03 | E21: DTA / (DTL)
B24: Net Deferred Tax ( liability) / Asset | D24: =SUM(D18:D21) -> -2881489.6
B26: Closing Balance of Deferred Tax Asset/(Liability)
C27: Asset | D27: Liability
B28: Opening Balance B/F - (DTL)/DTA | D28: =-+BS!H16*1000 -> -4666306.9 | E28: 6754.99
B29: Provision during the year (DTL)/ DTA | D29: =D24-D28 -> 1784817.2 | E29: -2088.68
B30: Closing Balance of Deferred Tax (Liability ) Asset | D30: =D24 -> -2881489.6 | E30: =SUM(E28:E29) -> 4666.31
B32: Net Def Tax (Liability)/ Asset at the end of the year - 31-3-2022 | D32: =D24 -> -2881489.6
B34: Entries to be passed for the year 2021-2022
B35: Deferred Tax asset/Liability | C35: =D29 -> 1784817.2
B36: To Profit & Loss account | D36: =+C35 -> 1784817.2
C38: =SUM(C35:C36) -> 1784817.2 | D38: =SUM(D35:D36) -> 1784817.2

Sheet FA  Register
A1: Depreciation Workings as per Companies Act 2013
A3: Example
A4: WDV Rate = 1 - ((salvage / cost) ^ (1 / life)) | AI4: Salvage Rate | AJ4: 0.05
A5: Sl No | B5: Asset Name | C5: Classification | D5: Rate of Dep | E5: Cost (Rs.) | F5: Addition during | G5: Date of Addition | H5: End Date | I5: Useful life | J5: No of days for which depn is charged in the year acquisition | K5: No of Days to be charged in the last year of useful life | L5: Dep to be calc in Last year on | M5: No. of Days | N5: Depn | O5: WDV as on 31.03.2009 | P5: No. of Days | Q5: Depn | R5: WDV as on 31.03.2010 | S5: No. of Days | T5: Depn | U5: WDV as on 31.03.2011 | V5: No. of Days | W5: Depn | X5: WDV as on 31.03.2012 | Y5: No. of Days | Z5: Depn | AA5: WDV as on 31.03.2013 | AB5: No. of Days | AC5: Depn | AD5: WDV as on 31.03.2014 | AE5: Total Depn | AF5: WDV | AG5: Check -Difference | AH5: Completed Life in Years | AI5: Usefule life as per Companies Act 2013 | AJ5: Balance Life | AK5: New Depreciation Rate | AL5: Adjust against Retained Earning | AM5: No. of Days | AN5: Depreciation already Charged at old Rate (books) | AO5: Depreciation at New Rate for FY 14-15 | AP5: Check - Written Down Value 31-3-15 | AQ5: New WDV as on 31/03/2015 | AR5: Check | AS5: Diff in Dep to be accounted in Mar 15 | AT5: WDV as per books (old Comp Act) | AU5: WDV to be shown as on 31/03/2015 | AW5: No of days | AX5: Dep-15-16 | AY5: WDV 15-16 | BA5: Dep-16-17 | BB5: WDV 16-17 | BC5: Use ful Life | BD5: Completed Life | BE5: Bal Life | BG5: Dep-17-18 | BH5: WDV 17-18 | BI5: Dep-18-19 | BJ5: WDV 18-19 | BK5: Dep- 19-20 | BL5: WDV -19-20 | BM5: Subsidy received | BN5: WDV as on 01-04-2020 | BO5: Dep--20-21 | BP5: WDV 20-21 | BQ5: Subsidy received | BR5: WDV as on 01-04-2021 | BS5: Dep-21-22 | BT5: WDV 21-22 | BU5: Dep-22-23 | BV5: WDV 22-23 | BW5: Dep-23-24 | BX5: WDV 23-24 | BY5: Dep-24-25 | BZ5: WDV 24-25 | CA5: Dep-25-26 | CB5: WDV 25-26 | CC5: Dep-26-27 | CD5: WDV 26-27 | CE5: Dep 27-28 | CF5: WDV 27-28 | CG5: Dep 28-29 | CH5: WDV 28-29 | CI5: Dep 29-30 | CJ5: WDV 29-30 | CK5: Dep 30-31 | CL5: WDV 30-31 | CM5: Dep -31-32 | CN5: WDV 31-32 | CO5: Dep 32-33 | CP5: WDV 32-33 | CQ5: Dep 33-34 | CR5: WDV 33-34 | CS5: Dep34-35 | CT5: WDV34-35 | CU5: Dep35-36 | CV5: WDV35-36 | CW5: Dep36-37 | CX5: WDV36-37 | CY5: Dep37-38 | CZ5: WDV37-38 | DA5: Dep38-39 | DB5: WDV38-39 | DC5: Dep39-40 | DD5: WDV39-40 | DE5: Dep40-41 | DF5: WDV40-41 | DG5: Dep41-42 | DH5: WDV41-42 | DI5: Dep42-43 | DJ5: WDV42-43 | DK5: Dep43-44 | DL5: WDV43-44 | DM5: Dep44-45 | DN5: WDV44-45 | DO5: Dep45-46 | DP5: WDV45-46 | DQ5: Dep46-47 | DR5: WDV46-47 | DS5: Dep47-48 | DT5: WDV47-48 | DU5: Dep48-49 | DV5: WDV48-49
M6: 39903 | N6: FY 08-09 | P6: 40268 | Q6: FY 09-10 | S6: 40633 | T6: FY 10-11 | V6: 40999 | W6: FY 11-12 | Y6: 41364 | Z6: FY 12-13 | AB6: 41729 | AC6: FY 13-14 | AE6: Till 31.03.14 | AF6: As on 31.03.14 | AH6: 41729 | AI6: (years) | AJ6: (years) | AM6: 42094 | AN6: FY14-15 | AT6: 42094 | AU6: Check | AW6: 42460 | AX6: 2015-16 | AZ6: 42825 | BD6: 42825 | BF6: 43190 | BI6: 43555 | BK6: 43921 | BO6: 44286 | BS6: 44651 | DW6: Salvage value | DX6: Check
