Workbook

Sheet P&L
B2: Dynamic Air Engineering India Pvt Ltd
B3: No 4, Boopathy Nagar, Industrial Estate
B4: Keelkattalai, Chennai - 600 117
B5: Provisional Statement of Profit and Loss for the period ended 31st March 2025
C6: Particulars | D6: Note No. | E6: Amount
B8: I. | C8: Revenue from operations | D8: 13 | E8: =+Notes!C150 -> 7.7579246e+08
B9: II. | C9: Other Income | D9: 14 | E9: =+Notes!C158 -> 757107
B10: III. | C10: Total Revenue (I + II) | E10: =SUM(E8:E9) -> 7.7654957e+08
B12: IV. | C12: Expenses
C13: Purchases and Direct Costs | D13: 15 | E13: =+Notes!C170 -> 6.7665428e+08
C14: Change in Inventories | D14: 16 | E14: =+Notes!C186 -> -10300000
C15: Employee Benefit Expenses | D15: 17 | E15: =+Notes!C196 -> 16676697
C16: Finance Costs | D16: 18 | E16: =+Notes!C215 -> 31222309
C17: Depreciation | E17: 19812135
C18: Other Expenses | D18: 19 | E18: =+Notes!C240 -> 29603934
C19: Total Expenses | E19: =SUM(E13:E18) -> 7.6366935e+08
B21: V. | C21: Profit Before Tax (III - IV) | E21: =+E10-E19 -> 12880215
B23: VI. | C23: Current tax | E23: =+E21*25% -> 3220053.9
B25: VII. | C25: Profit/(Loss) for the period (V - VI) | E25: =+E21-E23 -> 9660161.6
E28: For Dynamic Air Engineering India Pvt Ltd
E31: Managing Director

Sheet B&S
B2: Dynamic Air Engineering India Pvt Ltd
B3: No 4, Boopathy Nagar, Industrial Estate
B4: Keelkattalai, Chennai - 600 117
B5: Provisional Balance Sheet for the period ended 31st March 2025
C6: Particulars | D6: Note No. | E6: Amount
B8: I. | C8: Equity And Liabilities
B9: 1 | C9: Shareholders' Fund
C10: a) Share Capital | D10: 1 | E10: =+Notes!C11 -> 28500000
C11: b) Reserves & Surplus | D11: 2 | E11: =+Notes!C19 -> 67641629
C12: c) Share Premium | E12: =+Notes!C23 -> 16200000
B14: 2 | C14: Non- Current Liabilities
C15: a) Long term borrowings | D15: 3 | E15: =+Notes!C38 -> 76951624
B17: 3 | C17: Current Liabilities
C18: a) Short term borrowings | D18: 5 | E18: =+Notes!C57 -> 1.7396336e+08
C19: b) Trade payables | D19: 6 | E19: =+Notes!C64 -> 1.8322782e+08
C20: c) Other current liabilities | D20: 7 | E20: =+Notes!C84 -> 27992054
C21: d) Short term provisions | D21: 8 | E21: =+Notes!C91 -> 3220053.9
C23: Total | E23: =SUM(E10:E21) -> 5.7769653e+08
B25: II. | C25: Assets
C26: Non Current Assets
B27: 1 | C27: a) Fixed Assets | D27: 20 | E27: =+FA!K18 -> 1.8375011e+08
C28: i) Tangible assets
C29: b) Deferred tax assets / (liabilities) | D29: 4 | E29: =-Notes!C45 -> -2669673.8
B31: 2 | C31: Current Assets
C32: a) Inventories | D32: 9 | E32: =+Notes!C100 -> 162740000
C33: b) Trade receivables | D33: 10 | E33: =+Notes!C107 -> 1.7922907e+08
C34: c) Cash & cash equivalents | D34: 11 | E34: =+Notes!C114 -> 14937
C35: d) Short term loans & advances | D35: 12 | E35: =+Notes!C142 -> 54632084
C37: Total | E37: =SUM(E27:E35) -> 5.7769653e+08
E40: For Dynamic Air Engineering India Pvt Ltd
E43: Managing Director
E45: =+E23-E37 -> 0

Sheet Notes
B2: Note:1 Share Capital
B3: Particulars | C3: As at 31.03.25
B5: Authorised
B6: 65,00,000 Equity Shares of Rs 10 each | C6: =6500000*10 -> 65000000
B8: Issued, Subscribed & Paid up
B9: 28,50,000 Equity Shares of Rs 10 each | C9: =2850000*10 -> 28500000
B11: Total | C11: =+C9 -> 28500000
B13: Note:2 Reserves & Surplus
B14: Particulars | C14: As at 31.03.25
B16: Opening balance | C16: 57981468
B17: (+) Net Profit/ (Net Loss) for the period | C17: =+'P&L'!E25 -> 9660161.6
B19: Total | C19: =+C16+C17 -> 67641629
B21: Share Premium | C21: 16200000
B23: Total | C23: =SUM(C21:C21) -> 16200000
B26: Note:3 Long Term Borrowings
B27: Particulars | C27: As at 31.03.25
B29: Secured Loans
B30: HDFC TL - I | C30: 10665345
B31: HDFC TL - II | C31: 38330037
B32: HDFC TL GECL - IV | C32: 11393234
B33: Sundaram Vehicle Loan | C33: =495885+1722589 -> 2218474
B34: SIDBI Machinery Loan | C34: -5798
B35: Sundaram Machinery Loan | C35: =8127897+6222436 -> 14350333
B38: Total | C38: =SUM(C30:C35) -> 76951624
B40: Note: 4 Deferred Tax (Liability) / Asset
B41: Particulars | C41: As at 31.03.25
B43: Deferred Tax | C43: 2669673.8
B45: Total | C45: =SUM(C43:C43) -> 2669673.8
B47: Note: 5 Short Term Borrowings
B48: Particulars | C48: As at 31.03.25
B50: HDFC Bank - CC Account | C50: 1.161792e+08
B52: Adithya Birla Finance - Channel Finance | C52: =14599194+85702+504980 -> 15189876
B53: Tata Capital Services - Channel Finance | C53: 13094094
B54: NSIC | C54: 29500188
B57: Total | C57: =SUM(C50:C56) -> 1.7396336e+08
B59: Note: 6 Trade Payables
B60: Particulars | C60: As at 31.03.25
B62: Trade Payables | C62: =188552937.56-5325122.05 -> 1.8322782e+08
B64: Total | C64: =SUM(C62:C63) -> 1.8322782e+08
B66: Note: 7 Other Current Liabilities
...

Sheet FA
B3: Note : 20 Non Current Assets - Fixed Assets
C4: Fixed Assets | D4: Gross Block | G4: Accumulated Depreciation | J4: Net Block
D5: Balance as at 31'March 2024 | E5: Additions | F5: Balance as at 31'March 2025 | G5: Balance as at 31'March 2024 | H5: Depreciation for the year | I5: Balance as at 31'March 2025 | J5: Balance as at 31'March 2024 | K5: Balance as at 31'March 2025
B6: I | C6: Tangible Assets
B7: a | C7: Land | D7: 24942539 | F7: =+D7+E7 -> 24942539 | G7: 0 | I7: =+G7+H7 -> 0 | J7: =+D7-G7 -> 24942539 | K7: =F7-I7 -> 24942539
B8: b | C8: Factory Building | D8: =86789572.35+3268009.17 -> 90057582 | E8: =4066766.16-318688.92 -> 3748077.2 | F8: =+D8+E8 -> 93805659 | G8: 38378592 | H8: 4445242 | I8: =+G8+H8 -> 42823834 | J8: =+D8-G8 -> 51678989 | K8: =F8-I8 -> 50981824
B9: c | C9: Comptuers | D9: =2448377.84+350000 -> 2798377.8 | E9: 171497.49 | F9: =+D9+E9 -> 2969875.3 | G9: 2563077.8 | H9: 170690 | I9: =+G9+H9 -> 2733767.8 | J9: =+D9-G9 -> 235300.04 | K9: =F9-I9 -> 236107.53
B10: d | C10: Air Conditioners | D10: 442718.94 | E10: 38320.95 | F10: =+D10+E10 -> 481039.89 | G10: 286377.38 | H10: 72225 | I10: =+G10+H10 -> 358602.38 | J10: =+D10-G10 -> 156341.56 | K10: =F10-I10 -> 122437.51
B11: e | C11: Plant & Machineries | D11: 2.4843993e+08 | E11: =16804408.86-8844000 -> 7960408.9 | F11: =+D11+E11 -> 2.5640034e+08 | G11: 1.475119e+08 | H11: 13014405 | I11: =+G11+H11 -> 1.605263e+08 | J11: =+D11-G11 -> 1.0092803e+08 | K11: =F11-I11 -> 95874036
B12: f | C12: Invertor | D12: 25500 | F12: =+D12+E12 -> 25500 | G12: 24224.27 | I12: =+G12+H12 -> 24224.27 | J12: =+D12-G12 -> 1275.73 | K12: =F12-I12 -> 1275.73
B13: g | C13: Telephone Instruments | D13: 20948 | F13: =+D13+E13 -> 20948 | G13: 20546.35 | I13: =+G13+H13 -> 20546.35 | J13: =+D13-G13 -> 401.65 | K13: =F13-I13 -> 401.65
B14: h | C14: Office Equipments | D14: 1184555.4 | E14: 265128.33 | F14: =+D14+E14 -> 1449683.8 | G14: 959888.09 | H14: 96537 | I14: =+G14+H14 -> 1056425.1 | J14: =+D14-G14 -> 224667.33 | K14: =F14-I14 -> 393258.66
B15: i | C15: Electrical Installations | D15: 21030556 | E15: 583564.41 | F15: =+D15+E15 -> 21614121 | G15: 16295941 | H15: 992619 | I15: =+G15+H15 -> 17288560 | J15: =+D15-G15 -> 4734615.5 | K15: =F15-I15 -> 4325560.9
B16: j | C16: Vehicles | D16: 11432608 | E16: 3368139.5 | F16: =+D16+E16 -> 14800747 | G16: 8431135.9 | H16: 859193 | I16: =+G16+H16 -> 9290328.9 | J16: =+D16-G16 -> 3001472 | K16: =F16-I16 -> 5510418.5
B17: k | C17: Furiniture & Fixtures | D17: 2217345 | E17: 875038.04 | F17: =+D17+E17 -> 3092383 | G17: 1568906 | H17: 161224 | I17: =+G17+H17 -> 1730130 | J17: =+D17-G17 -> 648439.01 | K17: =F17-I17 -> 1362253.1
C18: Total | D18: =SUM(D7:D17) -> 4.0259266e+08 | E18: =SUM(E7:E17) -> 17010175 | F18: =SUM(F7:F17) -> 4.1960284e+08 | G18: =SUM(G7:G17) -> 2.1604059e+08 | H18: =SUM(H7:H17) -> 19812135 | I18: =SUM(I7:I17) -> 2.3585272e+08 | J18: =SUM(J7:J17) -> 1.8655207e+08 | K18: =SUM(K6:K17) -> 1.8375011e+08
