Workbook

Sheet P&L
B2: Dynamic Air Engineering India Pvt Ltd
B3: No 4, Boopathy Nagar, Industrial Estate
B4: Keelkattalai, Chennai - 600 117
B5: Provisional Statement of Profit and Loss for the period ended 31st March 2022
C6: Particulars | D6: Note No. | E6: Amount
B8: I. | C8: Revenue from operations | D8: 13 | E8: =+Notes!C144 -> 4.6079321e+08
B9: II. | C9: Other Income | D9: 14 | E9: =+Notes!C152 -> 338074.51
B10: III. | C10: Total Revenue (I + II) | E10: =SUM(E8:E9) -> 4.6113128e+08
B12: IV. | C12: Expenses
C13: Purchases and Direct Costs | D13: 15 | E13: =+Notes!C164 -> 3.8748237e+08
C14: Change in Inventories | D14: 16 | E14: =+Notes!C180 -> -37605374
C15: Employee Benefit Expenses | D15: 17 | E15: =+Notes!C190 -> 22687997
C16: Finance Costs | D16: 18 | E16: =+Notes!C207 -> 25055633
C17: Depreciation | E17: =+FA!H18 -> 31951276
C18: Other Expenses | D18: 19 | E18: =+Notes!C233 -> 20519236
C19: Total Expenses | E19: =SUM(E13:E18) -> 4.5009114e+08
B21: V. | C21: Profit Before Tax (III - IV) | E21: =+E10-E19 -> 11040144
B23: VI. | C23: Current tax | E23: =+E21*25% -> 2760036.1
B25: VII. | C25: Profit/(Loss) for the period (V - VI) | E25: =+E21-E23 -> 8280108.2
E28: For Dynamic Air Engineering India Pvt Ltd
E31: Managing Director

Sheet B&S
B2: Dynamic Air Engineering India Pvt Ltd
B3: No 4, Boopathy Nagar, Industrial Estate
B4: Keelkattalai, Chennai - 600 117
B5: Provisional Balance Sheet for the period ended 31st March 2022
C6: Particulars | D6: Note No. | E6: Amount
B8: I. | C8: Equity And Liabilities
B9: 1 | C9: Shareholders' Fund
C10: a) Share Capital | D10: 1 | E10: =+Notes!C11 -> 28500000
C11: b) Reserves & Surplus | D11: 2 | E11: =+Notes!C19 -> 47537623
C12: c) Share Premium | E12: =+Notes!C23 -> 16200000
B14: 2 | C14: Non- Current Liabilities
C15: a) Long term borrowings | D15: 3 | E15: =+Notes!C38 -> 1.7690903e+08
B17: 3 | C17: Current Liabilities
C18: a) Short term borrowings | D18: 5 | E18: =+Notes!C52 -> 37687912
C19: b) Trade payables | D19: 6 | E19: =+Notes!C59 -> 1.0931157e+08
C20: c) Other current liabilities | D20: 7 | E20: =+Notes!C79 -> 10861646
C21: d) Short term provisions | D21: 8 | E21: =+Notes!C86 -> 2755328.1
C23: Total | E23: =SUM(E10:E21) -> 4.2976311e+08
B25: II. | C25: Assets
C26: Non Current Assets
B27: 1 | C27: a) Fixed Assets | D27: 20 | E27: =+FA!K18 -> 2.0124949e+08
C28: i) Tangible assets
C29: b) Deferred tax assets / (liabilities) | D29: 4 | E29: =-Notes!C45 -> -4666306.8
B31: 2 | C31: Current Assets
C32: a) Inventories | D32: 9 | E32: =+Notes!C95 -> 94501381
C33: b) Trade receivables | D33: 10 | E33: =+Notes!C102 -> 94405231
C34: c) Cash & cash equivalents | D34: 11 | E34: =+Notes!C113 -> 528671.35
C35: d) Short term loans & advances | D35: 12 | E35: =+Notes!C136 -> 43744645
C37: Total | E37: =SUM(E27:E35) -> 4.2976311e+08
E40: For Dynamic Air Engineering India Pvt Ltd
E43: Managing Director

Sheet Notes
B2: Note:1 Share Capital
B3: Particulars | C3: As at 31.03.22
B5: Authorised
B6: 65,00,000 Equity Shares of Rs 10 each | C6: =6500000*10 -> 65000000
B8: Issued, Subscribed & Paid up
B9: 28,50,000 Equity Shares of Rs 10 each | C9: =2850000*10 -> 28500000
B11: Total | C11: =+C9 -> 28500000
B13: Note:2 Reserves & Surplus
B14: Particulars | C14: As at 31.03.22
B16: Opening balance | C16: 39257515
B17: (+) Net Profit/ (Net Loss) for the period | C17: =+'P&L'!E25 -> 8280108.2
B19: Total | C19: =+C16+C17 -> 47537623
B21: Share Premium | C21: 16200000
B23: Total | C23: =SUM(C21:C21) -> 16200000
B26: Note:3 Long Term Borrowings
B27: Particulars | C27: As at 31.03.22
B29: Secured Loans
B30: Indian Bank TL - I | C30: 27194129
B31: Indian Bank TL - II | C31: 97806491
B32: Indian Bank TL GECL - I | C32: 32498903
B33: Indian Bank TL GECL - II | C33: 18516842
B34: Indian Bank Vehicle Loan | C34: 683063
B35: Kotak Bank Vehicle Loan | C35: 209600
B38: Total | C38: =SUM(C30:C36) -> 1.7690903e+08
B40: Note: 4 Deferred Tax (Liability) / Asset
B41: Particulars | C41: As at 31.03.22
B43: Deferred Tax | C43: 4666306.8
B45: Total | C45: =SUM(C43:C43) -> 4666306.8
B47: Note: 5 Short Term Borrowings
B48: Particulars | C48: As at 31.03.22
B50: Indian Bank - CC Account | C50: 37687912
B52: Total | C52: =SUM(C50:C51) -> 37687912
B54: Note: 6 Trade Payables
B55: Particulars | C55: As at 31.03.22
B57: Trade Payables | C57: =111260993.66-1949422 -> 1.0931157e+08
B59: Total | C59: =SUM(C57:C58) -> 1.0931157e+08
B61: Note: 7 Other Current Liabilities
B62: Particulars | C62: As at 31.03.22
B64: Outstanding Expenses
B65: Salary & Wages payable | C65: =151490+1792127 -> 1943617
...

Sheet FA
B3: Note : 20 Non Current Assets - Fixed Assets
C4: Fixed Assets | D4: Gross Block | G4: Accumulated Depreciation | J4: Net Block
D5: Balance as at 31'March 2021 | E5: Additions | F5: Balance as at 31'March 2022 | G5: Balance as at 31'March 2021 | H5: Depreciation for the year | I5: Balance as at 31'March 2022 | J5: Balance as at 31'March 2021 | K5: Balance as at 31'March 2022
B6: I | C6: Tangible Assets
B7: a | C7: Land | D7: 24942539 | F7: =+D7+E7 -> 24942539 | G7: 0 | I7: =+G7+H7 -> 0 | J7: =+D7-G7 -> 24942539 | K7: =F7-I7 -> 24942539
B8: b | C8: Factory Building | D8: 82773607 | F8: =+D8+E8 -> 82773607 | G8: 22264801 | H8: 5747552 | I8: =+G8+H8 -> 28012353 | J8: =+D8-G8 -> 60508807 | K8: =F8-I8 -> 54761255
B9: c | C9: Comptuers | D9: 1400345.6 | E9: 852838.93 | F9: =+D9+E9 -> 2253184.6 | G9: 1129403.4 | H9: 154508 | I9: =+G9+H9 -> 1283911.4 | J9: =+D9-G9 -> 270942.27 | K9: =F9-I9 -> 969273.2
B10: d | C10: Air Conditioners | D10: 199784 | F10: =+D10+E10 -> 199784 | G10: 131838.82 | H10: 11419 | I10: =+G10+H10 -> 143257.82 | J10: =+D10-G10 -> 67945.18 | K10: =F10-I10 -> 56526.18
B11: e | C11: Plant & Machineries | D11: 2.0621007e+08 | E11: 5802500 | F11: =+D11+E11 -> 2.1201257e+08 | G11: 79634740 | H11: 22919650 | I11: =+G11+H11 -> 1.0255439e+08 | J11: =+D11-G11 -> 1.2657533e+08 | K11: =F11-I11 -> 1.0945818e+08
B12: f | C12: Invertor | D12: 25500 | F12: =+D12+E12 -> 25500 | G12: 23709.11 | H12: 170 | I12: =+G12+H12 -> 23879.11 | J12: =+D12-G12 -> 1790.89 | K12: =F12-I12 -> 1620.89
B13: g | C13: Telephone Instruments | D13: 20948 | F13: =+D13+E13 -> 20948 | G13: 20546.23 | H13: 0 | I13: =+G13+H13 -> 20546.23 | J13: =+D13-G13 -> 401.77 | K13: =F13-I13 -> 401.77
B14: h | C14: Office Equipments | D14: 768846.22 | E14: 82583.43 | F14: =+D14+E14 -> 851429.65 | G14: 480041.58 | H14: 112676 | I14: =+G14+H14 -> 592717.58 | J14: =+D14-G14 -> 288804.64 | K14: =F14-I14 -> 258712.07
B15: i | C15: Electrical Installations | D15: 19682887 | F15: =+D15+E15 -> 19682887 | G15: 10263618 | H15: 2438324 | I15: =+G15+H15 -> 12701942 | J15: 1425991.5 | K15: =F15-I15 -> 6980945
B16: j | C16: Vehicles | D16: 7298314.7 | E16: 2135210 | F16: =+D16+E16 -> 9433524.7 | G16: 5872323.2 | H16: 363931 | I16: =+G16+H16 -> 6236254.2 | J16: 9419269 | K16: =F16-I16 -> 3197270.5
B17: k | C17: Furiniture & Fixtures | D17: 1677356.5 | E17: 41450 | F17: =+D17+E17 -> 1718806.5 | G17: 892992.2 | H17: 203046 | I17: =+G17+H17 -> 1096038.2 | J17: =+D17-G17 -> 784364.27 | K17: =F17-I17 -> 622768.27
C18: Total | D18: =SUM(D7:D17) -> 3.450002e+08 | E18: =SUM(E7:E17) -> 8914582.4 | F18: =SUM(F7:F17) -> 3.5391478e+08 | G18: =SUM(G7:G17) -> 1.2071401e+08 | H18: =SUM(H7:H17) -> 31951276 | I18: =SUM(I7:I17) -> 1.5266529e+08 | J18: =SUM(J7:J17) -> 2.2428618e+08 | K18: =SUM(K6:K17) -> 2.0124949e+08

Sheet Sheet1
