Workbook

Sheet P&L
B2: Dynamic Air Engineering India Pvt Ltd
B3: No 4, Boopathy Nagar, Industrial Estate
B4: Keelkattalai, Chennai - 600 117
B5: Provisional Statement of Profit and Loss for the period ended 31st March 2023
C6: Particulars | D6: Note No. | E6: Amount
B8: I. | C8: Revenue from operations | D8: 13 | E8: =+Notes!C148 -> 6.943727e+08
B9: II. | C9: Other Income | D9: 14 | E9: =+Notes!C156 -> 1692373.3 | G9: =E9/10^7 -> 0.16923733
B10: III. | C10: Total Revenue (I + II) | E10: =SUM(E8:E9) -> 6.9606507e+08 | G10: =E10/10^7 -> 69.606507
G11: =E11/10^7 -> 0
B12: IV. | C12: Expenses | G12: =E12/10^7 -> 0
C13: Purchases and Direct Costs | D13: 15 | E13: =+Notes!C168 -> 6.4815384e+08 | G13: =E13/10^7 -> 64.815384
C14: Change in Inventories | D14: 16 | E14: =+Notes!C184 -> -55223620 | G14: =E14/10^7 -> -5.522362
C15: Employee Benefit Expenses | D15: 17 | E15: =+Notes!C194 -> 11737846 | G15: =E15/10^7 -> 1.1737846
C16: Finance Costs | D16: 18 | E16: =+Notes!C218 -> 26089553 | G16: =E16/10^7 -> 2.6089553
C17: Depreciation | E17: =+FA!H18 -> 27954173 | G17: =E17/10^7 -> 2.7954173
C18: Other Expenses | D18: 19 | E18: =+Notes!C244 -> 24743397 | G18: =E18/10^7 -> 2.4743397
C19: Total Expenses | E19: =SUM(E13:E18) -> 6.8345519e+08 | G19: =E19/10^7 -> 68.345519
G20: =E20/10^7 -> 0
B21: V. | C21: Profit Before Tax (III - IV) | E21: =+E10-E19 -> 12609880 | G21: =E21/10^7 -> 1.260988
G22: =E22/10^7 -> 0
B23: VI. | C23: Current tax | E23: =+E21*25% -> 3152470 | G23: =E23/10^7 -> 0.315247
G24: =E24/10^7 -> 0
B25: VII. | C25: Profit/(Loss) for the period (V - VI) | E25: =+E21-E23 -> 9457410 | G25: =E25/10^7 -> 0.945741
E28: For Dynamic Air Engineering India Pvt Ltd
E31: Managing Director

Sheet B&S
B2: Dynamic Air Engineering India Pvt Ltd
B3: No 4, Boopathy Nagar, Industrial Estate
B4: Keelkattalai, Chennai - 600 117
B5: Provisional Balance Sheet for the period ended 31st March 2023
C6: Particulars | D6: Note No. | E6: Amount
B8: I. | C8: Equity And Liabilities
B9: 1 | C9: Shareholders' Fund
C10: a) Share Capital | D10: 1 | E10: =+Notes!C11 -> 28500000
C11: b) Reserves & Surplus | D11: 2 | E11: =+Notes!C19 -> 56607040
C12: c) Share Premium | E12: =+Notes!C23 -> 16200000
B14: 2 | C14: Non- Current Liabilities
C15: a) Long term borrowings | D15: 3 | E15: =+Notes!C40 -> 1.9969821e+08
B17: 3 | C17: Current Liabilities
C18: a) Short term borrowings | D18: 5 | E18: =+Notes!C54 -> 1.2248421e+08
C19: b) Trade payables | D19: 6 | E19: =+Notes!C61 -> 83726013
C20: c) Other current liabilities | D20: 7 | E20: =+Notes!C81 -> 40333112
C21: d) Short term provisions | D21: 8 | E21: =+Notes!C88 -> 3152470
C23: Total | E23: =SUM(E10:E21) -> 5.5070106e+08
B25: II. | C25: Assets
C26: Non Current Assets
B27: 1 | C27: a) Fixed Assets | D27: 20 | E27: =+FA!K18 -> 2.1296918e+08
C28: i) Tangible assets
C29: b) Deferred tax assets / (liabilities) | D29: 4 | E29: =-Notes!C47 -> -2881489.9
B31: 2 | C31: Current Assets
C32: a) Inventories | D32: 9 | E32: =+Notes!C97 -> 149725000
C33: b) Trade receivables | D33: 10 | E33: =+Notes!C104 -> 1.4534532e+08
C34: c) Cash & cash equivalents | D34: 11 | E34: =+Notes!C115 -> 124983.44
C35: d) Short term loans & advances | D35: 12 | E35: =+Notes!C140 -> 45418066
C37: Total | E37: =SUM(E27:E35) -> 5.5070106e+08
E40: For Dynamic Air Engineering India Pvt Ltd
E43: Managing Director
E45: =+E23-E37 -> 0

Sheet Notes
B2: Note:1 Share Capital
B3: Particulars | C3: As at 31.03.23
B5: Authorised
B6: 65,00,000 Equity Shares of Rs 10 each | C6: =6500000*10 -> 65000000
B8: Issued, Subscribed & Paid up
B9: 28,50,000 Equity Shares of Rs 10 each | C9: =2850000*10 -> 28500000
B11: Total | C11: =+C9 -> 28500000
B13: Note:2 Reserves & Surplus
B14: Particulars | C14: As at 31.03.23
B16: Opening balance | C16: 47149630
B17: (+) Net Profit/ (Net Loss) for the period | C17: =+'P&L'!E25 -> 9457410
B19: Total | C19: =+C16+C17 -> 56607040
B21: Share Premium | C21: 16200000
B23: Total | C23: =SUM(C21:C21) -> 16200000
B26: Note:3 Long Term Borrowings
B27: Particulars | C27: As at 31.03.23
B29: Secured Loans
B30: HDFC TL - I | C30: 21911951
B31: HDFC TL - II | C31: 78748953
B32: HDFC TL GECL - III | C32: 21411543
B33: HDFC TL GECL - IV | C33: 18400000
B34: HDFC TL - V | C34: 29795507
B35: Indian Bank Vehicle Loan | C35: 454601
B36: SIDBI Machinery Loan | C36: 15295783
B37: Sundaram Machinery Loan | C37: =13675870+4000 -> 13679870
B40: Total | C40: =SUM(C30:C37) -> 1.9969821e+08
B42: Note: 4 Deferred Tax (Liability) / Asset
B43: Particulars | C43: As at 31.03.23
B45: Deferred Tax | C45: 2881489.9
B47: Total | C47: =SUM(C45:C45) -> 2881489.9
B49: Note: 5 Short Term Borrowings
B50: Particulars | C50: As at 31.03.23
B52: HDFC Bank - CC Account | C52: 1.2248421e+08
B54: Total | C54: =SUM(C52:C53) -> 1.2248421e+08
B56: Note: 6 Trade Payables
B57: Particulars | C57: As at 31.03.23
B59: Trade Payables | C59: 83726013
B61: Total | C61: =SUM(C59:C60) -> 83726013
B63: Note: 7 Other Current Liabilities
B64: Particulars | C64: As at 31.03.23
...

Sheet FA
B3: Note : 20 Non Current Assets - Fixed Assets
C4: Fixed Assets | D4: Gross Block | G4: Accumulated Depreciation | J4: Net Block
D5: Balance as at 31'March 2022 | E5: Additions | F5: Balance as at 31'March 2023 | G5: Balance as at 31'March 2022 | H5: Depreciation for the year | I5: Balance as at 31'March 2023 | J5: Balance as at 31'March 2022 | K5: Balance as at 31'March 2023
B6: I | C6: Tangible Assets
B7: a | C7: Land | D7: 24942539 | F7: =+D7+E7 -> 24942539 | G7: 0 | I7: =+G7+H7 -> 0 | J7: =+D7-G7 -> 24942539 | K7: =F7-I7 -> 24942539
B8: b | C8: Factory Building | D8: 82773607 | E8: 2954596 | F8: =+D8+E8 -> 85728203 | G8: 28012353 | H8: 5201608.1 | I8: =+G8+H8 -> 33213962 | J8: 54761255 | K8: =F8-I8 -> 52514242
B9: c | C9: Comptuers | D9: =1878184.58+275000 -> 2153184.6 | E9: 448499.25 | F9: =+D9+E9 -> 2601683.8 | G9: 1445113.2 | H9: 415473.94 | I9: =+G9+H9 -> 1860587.1 | J9: =+D9-G9 -> 708071.39 | K9: =F9-I9 -> 741096.7
B10: d | C10: Air Conditioners | D10: 199784 | E10: 34613 | F10: =+D10+E10 -> 234397 | G10: 184785.67 | H10: 3460 | I10: =+G10+H10 -> 188245.67 | J10: =+D10-G10 -> 14998.33 | K10: =F10-I10 -> 46151.33
B11: e | C11: Plant & Machineries | D11: 2.1201257e+08 | E11: =32674810-98000 -> 32576810 | F11: =+D11+E11 -> 2.4458938e+08 | G11: 1.023832e+08 | H11: 19850328 | I11: =+G11+H11 -> 1.2223353e+08 | J11: =+D11-G11 -> 1.0962937e+08 | K11: =F11-I11 -> 1.2235585e+08
B12: f | C12: Invertor | D12: 25500 | E12: 0 | F12: =+D12+E12 -> 25500 | G12: 24224.27 | H12: 0 | I12: =+G12+H12 -> 24224.27 | J12: =+D12-G12 -> 1275.73 | K12: =F12-I12 -> 1275.73
B13: g | C13: Telephone Instruments | D13: 20948 | E13: 0 | F13: =+D13+E13 -> 20948 | G13: 20546.35 | H13: 0 | I13: =+G13+H13 -> 20546.35 | J13: =+D13-G13 -> 401.65 | K13: =F13-I13 -> 401.65
B14: h | C14: Office Equipments | D14: 851429.65 | E14: 264715.69 | F14: =+D14+E14 -> 1116145.3 | G14: 656016.6 | H14: 87796 | I14: =+G14+H14 -> 743812.6 | J14: =+D14-G14 -> 195413.05 | K14: =F14-I14 -> 372332.74
B15: i | C15: Electrical Installations | D15: 19682887 | E15: 1303919.5 | F15: =+D15+E15 -> 20986806 | G15: 12701942 | H15: 1807126 | I15: =+G15+H15 -> 14509068 | J15: 1425991.5 | K15: =F15-I15 -> 6477738.5
B16: j | C16: Vehicles | D16: 9433524.7 | E16: =799083.25+1200000 -> 1999083.2 | F16: =+D16+E16 -> 11432608 | G16: 6409423.4 | H16: 427675 | I16: =+G16+H16 -> 6837098.4 | J16: 9419269 | K16: =F16-I16 -> 4595509.6
B17: k | C17: Furiniture & Fixtures | D17: 1718806.5 | E17: 461950 | F17: =+D17+E17 -> 2180756.5 | G17: 1098007.7 | H17: 160706 | I17: =+G17+H17 -> 1258713.7 | J17: =+D17-G17 -> 620798.79 | K17: =F17-I17 -> 922042.79
C18: Total | D18: =SUM(D7:D17) -> 3.5381478e+08 | E18: =SUM(E7:E17) -> 40044187 | F18: =SUM(F7:F17) -> 3.9385896e+08 | G18: =SUM(G7:G17) -> 1.5293561e+08 | H18: =SUM(H7:H17) -> 27954173 | I18: =SUM(I7:I17) -> 1.8088979e+08 | J18: =SUM(J7:J17) -> 2.0171938e+08 | K18: =SUM(K6:K17) -> 2.1296918e+08
